[INFO] :: [10/07/2015 23:04:52] :: [home:index:info] [12] :: chargement_page /
[ERROR] :: [10/07/2015 23:09:51] :: [base:handle_uncaught_exception:django.request] [256] :: Internal Server Error: /
Traceback (most recent call last):
  File "/home/chrysa/Bureau/42_work/framework/venv/lib/python3.4/site-packages/django/core/handlers/base.py", line 132, in get_response
    response = wrapped_callback(request, *callback_args, **callback_kwargs)
  File "/home/chrysa/Bureau/42_work/framework/app/core/home.py", line 12, in index
    logger.info(info_load_log_message(request))
  File "/home/chrysa/Bureau/42_work/framework/app/generate_logs/functions.py", line 5, in info_load_log_message
    return 'chargement de la page ' + request.META['PATH_INFO'] + ' par ' + request.user
TypeError: Can't convert 'SimpleLazyObject' object to str implicitly
[ERROR] :: [10/07/2015 23:10:11] :: [base:handle_uncaught_exception:django.request] [256] :: Internal Server Error: /
Traceback (most recent call last):
  File "/home/chrysa/Bureau/42_work/framework/venv/lib/python3.4/site-packages/django/core/handlers/base.py", line 132, in get_response
    response = wrapped_callback(request, *callback_args, **callback_kwargs)
  File "/home/chrysa/Bureau/42_work/framework/app/core/home.py", line 12, in index
    logger.info(info_load_log_message(request))
  File "/home/chrysa/Bureau/42_work/framework/app/generate_logs/functions.py", line 4, in info_load_log_message
    return 'chargement de la page ' + request.META['PATH_INFO'] + ' par ' + request.user
TypeError: Can't convert 'SimpleLazyObject' object to str implicitly
[INFO] :: [10/07/2015 23:10:46] :: [home:index:info] [12] :: chargement de la page / par AnonymousUser
[INFO] :: [10/07/2015 23:14:42] :: [views:display_all:info] [21] :: chargement de la page /forum/ par admin
[INFO] :: [10/07/2015 23:14:50] :: [views:display_all:info] [21] :: chargement de la page /forum/ par admin
[ERROR] :: [10/07/2015 23:16:24] :: [base:handle_uncaught_exception:django.request] [256] :: Internal Server Error: /log/info/
Traceback (most recent call last):
  File "/home/chrysa/Bureau/42_work/framework/venv/lib/python3.4/site-packages/django/core/handlers/base.py", line 132, in get_response
    response = wrapped_callback(request, *callback_args, **callback_kwargs)
  File "/home/chrysa/Bureau/42_work/framework/venv/lib/python3.4/site-packages/django/contrib/auth/decorators.py", line 22, in _wrapped_view
    return view_func(request, *args, **kwargs)
  File "/home/chrysa/Bureau/42_work/framework/app/generate_logs/views.py", line 60, in display_log
    log.append(
AttributeError: 'NoneType' object has no attribute 'append'
[INFO] :: [10/07/2015 23:16:47] :: [home:index:info] [12] :: chargement de la page / par admin
[INFO] :: [10/07/2015 23:37:47] :: [home:index:info] [12] :: chargement de la page / par admin
[INFO] :: [10/07/2015 23:39:37] :: [home:index:info] [13] :: chargement de la page / par admin
[INFO] :: [10/07/2015 23:40:02] :: [home:index:info] [13] :: chargement de la page / par admin
[INFO] :: [10/07/2015 23:40:37] :: [home:index:info] [13] :: chargement de la page / par admin
[INFO] :: [10/07/2015 23:41:53] :: [home:index:info] [13] :: chargement de la page / par admin
[INFO] :: [11/07/2015 09:08:34] :: [views:display_all:info] [22] :: chargement de la page /forum/ par admin
[INFO] :: [11/07/2015 09:11:52] :: [views:display_all:info] [22] :: chargement de la page /forum/ par admin
[INFO] :: [11/07/2015 20:27:36] :: [home:index:info] [13] :: chargement de la page / par AnonymousUser
[INFO] :: [11/07/2015 20:27:36] :: [views:select_login:info] [83] :: chargement de la page /profil/login par AnonymousUser
[INFO] :: [11/07/2015 20:27:36] :: [views:select_login:info] [83] :: chargement de la page /profil/login par AnonymousUser
[INFO] :: [11/07/2015 20:27:36] :: [views:select_login:info] [83] :: chargement de la page /profil/login par AnonymousUser
[INFO] :: [11/07/2015 20:27:36] :: [views:select_login:info] [83] :: chargement de la page /profil/login par AnonymousUser
[INFO] :: [11/07/2015 20:27:36] :: [views:select_login:info] [83] :: chargement de la page /profil/login par AnonymousUser
[INFO] :: [11/07/2015 20:27:36] :: [views:select_login:info] [83] :: chargement de la page /profil/login par AnonymousUser
[INFO] :: [11/07/2015 20:27:36] :: [views:register_user:info] [28] :: chargement de la page /profil/register par AnonymousUser
[INFO] :: [11/07/2015 20:27:36] :: [views:register_user:info] [52] :: creation du compte AnonymousUser
[ERROR] :: [11/07/2015 20:27:36] :: [base:handle_uncaught_exception:django.request] [256] :: Internal Server Error: /profil/register
Traceback (most recent call last):
  File "/home/chrysa/Bureau/42_work/framework/venv/lib/python3.4/site-packages/django/utils/datastructures.py", line 320, in __getitem__
    list_ = super(MultiValueDict, self).__getitem__(key)
KeyError: 'next'

During handling of the above exception, another exception occurred:

Traceback (most recent call last):
  File "/home/chrysa/Bureau/42_work/framework/venv/lib/python3.4/site-packages/django/core/handlers/base.py", line 132, in get_response
    response = wrapped_callback(request, *callback_args, **callback_kwargs)
  File "/home/chrysa/Bureau/42_work/framework/app/profil/views.py", line 54, in register_user
    if request.GET['next'] != reverse('register'):
  File "/home/chrysa/Bureau/42_work/framework/venv/lib/python3.4/site-packages/django/utils/datastructures.py", line 322, in __getitem__
    raise MultiValueDictKeyError(repr(key))
django.utils.datastructures.MultiValueDictKeyError: "'next'"
[INFO] :: [11/07/2015 20:27:36] :: [views:register_user:info] [28] :: chargement de la page /profil/register par AnonymousUser
[INFO] :: [11/07/2015 20:27:36] :: [views:register_user:info] [52] :: creation du compte AnonymousUser
[ERROR] :: [11/07/2015 20:27:36] :: [base:handle_uncaught_exception:django.request] [256] :: Internal Server Error: /profil/register
Traceback (most recent call last):
  File "/home/chrysa/Bureau/42_work/framework/venv/lib/python3.4/site-packages/django/utils/datastructures.py", line 320, in __getitem__
    list_ = super(MultiValueDict, self).__getitem__(key)
KeyError: 'next'

During handling of the above exception, another exception occurred:

Traceback (most recent call last):
  File "/home/chrysa/Bureau/42_work/framework/venv/lib/python3.4/site-packages/django/core/handlers/base.py", line 132, in get_response
    response = wrapped_callback(request, *callback_args, **callback_kwargs)
  File "/home/chrysa/Bureau/42_work/framework/app/profil/views.py", line 54, in register_user
    if request.GET['next'] != reverse('register'):
  File "/home/chrysa/Bureau/42_work/framework/venv/lib/python3.4/site-packages/django/utils/datastructures.py", line 322, in __getitem__
    raise MultiValueDictKeyError(repr(key))
django.utils.datastructures.MultiValueDictKeyError: "'next'"
[INFO] :: [11/07/2015 20:27:36] :: [views:register_user:info] [28] :: chargement de la page /profil/register par AnonymousUser
[INFO] :: [11/07/2015 20:27:36] :: [views:register_user:info] [28] :: chargement de la page /profil/register par AnonymousUser
[INFO] :: [11/07/2015 20:27:36] :: [views:register_user:info] [28] :: chargement de la page /profil/register par AnonymousUser
[INFO] :: [11/07/2015 20:27:36] :: [views:register_user:info] [28] :: chargement de la page /profil/register par AnonymousUser
[INFO] :: [11/07/2015 20:28:08] :: [home:index:info] [13] :: chargement de la page / par AnonymousUser
[INFO] :: [11/07/2015 20:28:08] :: [views:select_login:info] [83] :: chargement de la page /profil/login par AnonymousUser
[INFO] :: [11/07/2015 20:28:08] :: [views:select_login:info] [83] :: chargement de la page /profil/login par AnonymousUser
[INFO] :: [11/07/2015 20:28:08] :: [views:select_login:info] [83] :: chargement de la page /profil/login par AnonymousUser
[INFO] :: [11/07/2015 20:28:08] :: [views:select_login:info] [83] :: chargement de la page /profil/login par AnonymousUser
[INFO] :: [11/07/2015 20:28:08] :: [views:select_login:info] [83] :: chargement de la page /profil/login par AnonymousUser
[INFO] :: [11/07/2015 20:28:08] :: [views:select_login:info] [83] :: chargement de la page /profil/login par AnonymousUser
[INFO] :: [11/07/2015 20:28:08] :: [views:register_user:info] [28] :: chargement de la page /profil/register par AnonymousUser
[INFO] :: [11/07/2015 20:28:08] :: [views:register_user:info] [52] :: creation du compte AnonymousUser
[ERROR] :: [11/07/2015 20:28:08] :: [base:handle_uncaught_exception:django.request] [256] :: Internal Server Error: /profil/register
Traceback (most recent call last):
  File "/home/chrysa/Bureau/42_work/framework/venv/lib/python3.4/site-packages/django/utils/datastructures.py", line 320, in __getitem__
    list_ = super(MultiValueDict, self).__getitem__(key)
KeyError: 'next'

During handling of the above exception, another exception occurred:

Traceback (most recent call last):
  File "/home/chrysa/Bureau/42_work/framework/venv/lib/python3.4/site-packages/django/core/handlers/base.py", line 132, in get_response
    response = wrapped_callback(request, *callback_args, **callback_kwargs)
  File "/home/chrysa/Bureau/42_work/framework/app/profil/views.py", line 54, in register_user
    if request.GET['next'] != reverse('register'):
  File "/home/chrysa/Bureau/42_work/framework/venv/lib/python3.4/site-packages/django/utils/datastructures.py", line 322, in __getitem__
    raise MultiValueDictKeyError(repr(key))
django.utils.datastructures.MultiValueDictKeyError: "'next'"
[INFO] :: [11/07/2015 20:28:08] :: [views:register_user:info] [28] :: chargement de la page /profil/register par AnonymousUser
[INFO] :: [11/07/2015 20:28:08] :: [views:register_user:info] [52] :: creation du compte AnonymousUser
[ERROR] :: [11/07/2015 20:28:08] :: [base:handle_uncaught_exception:django.request] [256] :: Internal Server Error: /profil/register
Traceback (most recent call last):
  File "/home/chrysa/Bureau/42_work/framework/venv/lib/python3.4/site-packages/django/utils/datastructures.py", line 320, in __getitem__
    list_ = super(MultiValueDict, self).__getitem__(key)
KeyError: 'next'

During handling of the above exception, another exception occurred:

Traceback (most recent call last):
  File "/home/chrysa/Bureau/42_work/framework/venv/lib/python3.4/site-packages/django/core/handlers/base.py", line 132, in get_response
    response = wrapped_callback(request, *callback_args, **callback_kwargs)
  File "/home/chrysa/Bureau/42_work/framework/app/profil/views.py", line 54, in register_user
    if request.GET['next'] != reverse('register'):
  File "/home/chrysa/Bureau/42_work/framework/venv/lib/python3.4/site-packages/django/utils/datastructures.py", line 322, in __getitem__
    raise MultiValueDictKeyError(repr(key))
django.utils.datastructures.MultiValueDictKeyError: "'next'"
[INFO] :: [11/07/2015 20:28:08] :: [views:register_user:info] [28] :: chargement de la page /profil/register par AnonymousUser
[INFO] :: [11/07/2015 20:28:08] :: [views:register_user:info] [28] :: chargement de la page /profil/register par AnonymousUser
[INFO] :: [11/07/2015 20:28:08] :: [views:register_user:info] [28] :: chargement de la page /profil/register par AnonymousUser
[INFO] :: [11/07/2015 20:28:08] :: [views:register_user:info] [28] :: chargement de la page /profil/register par AnonymousUser
[INFO] :: [12/07/2015 14:24:05] :: [home:index:info] [13] :: chargement de la page / par AnonymousUser
[INFO] :: [12/07/2015 14:24:05] :: [views:select_login:info] [83] :: chargement de la page /profil/login par AnonymousUser
[INFO] :: [12/07/2015 14:24:05] :: [views:select_login:info] [83] :: chargement de la page /profil/login par AnonymousUser
[INFO] :: [12/07/2015 14:24:06] :: [views:select_login:info] [83] :: chargement de la page /profil/login par AnonymousUser
[INFO] :: [12/07/2015 14:24:06] :: [views:select_login:info] [83] :: chargement de la page /profil/login par AnonymousUser
[INFO] :: [12/07/2015 14:24:06] :: [views:select_login:info] [83] :: chargement de la page /profil/login par AnonymousUser
[INFO] :: [12/07/2015 14:24:06] :: [views:select_login:info] [83] :: chargement de la page /profil/login par AnonymousUser
[INFO] :: [12/07/2015 14:24:06] :: [views:register_user:info] [28] :: chargement de la page /profil/register par AnonymousUser
[INFO] :: [12/07/2015 14:24:06] :: [views:register_user:info] [52] :: creation du compte AnonymousUser
[ERROR] :: [12/07/2015 14:24:06] :: [base:handle_uncaught_exception:django.request] [256] :: Internal Server Error: /profil/register
Traceback (most recent call last):
  File "D:\42_work\framework\venv\lib\site-packages\django\utils\datastructures.py", line 320, in __getitem__
    list_ = super(MultiValueDict, self).__getitem__(key)
KeyError: 'next'

During handling of the above exception, another exception occurred:

Traceback (most recent call last):
  File "D:\42_work\framework\venv\lib\site-packages\django\core\handlers\base.py", line 132, in get_response
    response = wrapped_callback(request, *callback_args, **callback_kwargs)
  File "D:\42_work\framework\app\profil\views.py", line 54, in register_user
    if request.GET['next'] != reverse('register'):
  File "D:\42_work\framework\venv\lib\site-packages\django\utils\datastructures.py", line 322, in __getitem__
    raise MultiValueDictKeyError(repr(key))
django.utils.datastructures.MultiValueDictKeyError: "'next'"
[INFO] :: [12/07/2015 14:24:06] :: [views:register_user:info] [28] :: chargement de la page /profil/register par AnonymousUser
[INFO] :: [12/07/2015 14:24:06] :: [views:register_user:info] [52] :: creation du compte AnonymousUser
[ERROR] :: [12/07/2015 14:24:06] :: [base:handle_uncaught_exception:django.request] [256] :: Internal Server Error: /profil/register
Traceback (most recent call last):
  File "D:\42_work\framework\venv\lib\site-packages\django\utils\datastructures.py", line 320, in __getitem__
    list_ = super(MultiValueDict, self).__getitem__(key)
KeyError: 'next'

During handling of the above exception, another exception occurred:

Traceback (most recent call last):
  File "D:\42_work\framework\venv\lib\site-packages\django\core\handlers\base.py", line 132, in get_response
    response = wrapped_callback(request, *callback_args, **callback_kwargs)
  File "D:\42_work\framework\app\profil\views.py", line 54, in register_user
    if request.GET['next'] != reverse('register'):
  File "D:\42_work\framework\venv\lib\site-packages\django\utils\datastructures.py", line 322, in __getitem__
    raise MultiValueDictKeyError(repr(key))
django.utils.datastructures.MultiValueDictKeyError: "'next'"
[INFO] :: [12/07/2015 14:24:06] :: [views:register_user:info] [28] :: chargement de la page /profil/register par AnonymousUser
[INFO] :: [12/07/2015 14:24:06] :: [views:register_user:info] [28] :: chargement de la page /profil/register par AnonymousUser
[INFO] :: [12/07/2015 14:24:06] :: [views:register_user:info] [28] :: chargement de la page /profil/register par AnonymousUser
[INFO] :: [12/07/2015 14:24:06] :: [views:register_user:info] [28] :: chargement de la page /profil/register par AnonymousUser
[INFO] :: [12/07/2015 14:24:11] :: [home:index:info] [13] :: chargement de la page / par admin
[WARNING] :: [12/07/2015 14:24:12] :: [base:get_response:django.request] [170] :: Not Found: /favicon.ico
[INFO] :: [12/07/2015 14:24:15] :: [home:index:info] [13] :: chargement de la page / par admin
[INFO] :: [12/07/2015 14:24:18] :: [home:index:info] [13] :: chargement de la page / par admin
[INFO] :: [12/07/2015 14:24:40] :: [home:index:info] [13] :: chargement de la page / par AnonymousUser
[INFO] :: [12/07/2015 14:24:40] :: [views:select_login:info] [83] :: chargement de la page /profil/login par AnonymousUser
[INFO] :: [12/07/2015 14:24:40] :: [views:select_login:info] [83] :: chargement de la page /profil/login par AnonymousUser
[INFO] :: [12/07/2015 14:24:40] :: [views:select_login:info] [83] :: chargement de la page /profil/login par AnonymousUser
[INFO] :: [12/07/2015 14:24:40] :: [views:select_login:info] [83] :: chargement de la page /profil/login par AnonymousUser
[INFO] :: [12/07/2015 14:24:40] :: [views:select_login:info] [83] :: chargement de la page /profil/login par AnonymousUser
[INFO] :: [12/07/2015 14:24:40] :: [views:select_login:info] [83] :: chargement de la page /profil/login par AnonymousUser
[INFO] :: [12/07/2015 14:24:40] :: [views:register_user:info] [28] :: chargement de la page /profil/register par AnonymousUser
[INFO] :: [12/07/2015 14:24:40] :: [views:register_user:info] [52] :: creation du compte AnonymousUser
[ERROR] :: [12/07/2015 14:24:40] :: [base:handle_uncaught_exception:django.request] [256] :: Internal Server Error: /profil/register
Traceback (most recent call last):
  File "D:\42_work\framework\venv\lib\site-packages\django\utils\datastructures.py", line 320, in __getitem__
    list_ = super(MultiValueDict, self).__getitem__(key)
KeyError: 'next'

During handling of the above exception, another exception occurred:

Traceback (most recent call last):
  File "D:\42_work\framework\venv\lib\site-packages\django\core\handlers\base.py", line 132, in get_response
    response = wrapped_callback(request, *callback_args, **callback_kwargs)
  File "D:\42_work\framework\app\profil\views.py", line 54, in register_user
    if request.GET['next'] != reverse('register'):
  File "D:\42_work\framework\venv\lib\site-packages\django\utils\datastructures.py", line 322, in __getitem__
    raise MultiValueDictKeyError(repr(key))
django.utils.datastructures.MultiValueDictKeyError: "'next'"
[INFO] :: [12/07/2015 14:24:40] :: [views:register_user:info] [28] :: chargement de la page /profil/register par AnonymousUser
[INFO] :: [12/07/2015 14:24:40] :: [views:register_user:info] [52] :: creation du compte AnonymousUser
[ERROR] :: [12/07/2015 14:24:40] :: [base:handle_uncaught_exception:django.request] [256] :: Internal Server Error: /profil/register
Traceback (most recent call last):
  File "D:\42_work\framework\venv\lib\site-packages\django\utils\datastructures.py", line 320, in __getitem__
    list_ = super(MultiValueDict, self).__getitem__(key)
KeyError: 'next'

During handling of the above exception, another exception occurred:

Traceback (most recent call last):
  File "D:\42_work\framework\venv\lib\site-packages\django\core\handlers\base.py", line 132, in get_response
    response = wrapped_callback(request, *callback_args, **callback_kwargs)
  File "D:\42_work\framework\app\profil\views.py", line 54, in register_user
    if request.GET['next'] != reverse('register'):
  File "D:\42_work\framework\venv\lib\site-packages\django\utils\datastructures.py", line 322, in __getitem__
    raise MultiValueDictKeyError(repr(key))
django.utils.datastructures.MultiValueDictKeyError: "'next'"
[INFO] :: [12/07/2015 14:24:40] :: [views:register_user:info] [28] :: chargement de la page /profil/register par AnonymousUser
[INFO] :: [12/07/2015 14:24:40] :: [views:register_user:info] [28] :: chargement de la page /profil/register par AnonymousUser
[INFO] :: [12/07/2015 14:24:40] :: [views:register_user:info] [28] :: chargement de la page /profil/register par AnonymousUser
[INFO] :: [12/07/2015 14:24:40] :: [views:register_user:info] [28] :: chargement de la page /profil/register par AnonymousUser
[INFO] :: [12/07/2015 13:27:56] :: [home:index:info] [13] :: chargement de la page / par AnonymousUser
[INFO] :: [12/07/2015 13:27:56] :: [views:select_login:info] [83] :: chargement de la page /profil/login par AnonymousUser
[INFO] :: [12/07/2015 13:27:56] :: [views:select_login:info] [83] :: chargement de la page /profil/login par AnonymousUser
[INFO] :: [12/07/2015 13:27:56] :: [views:select_login:info] [83] :: chargement de la page /profil/login par AnonymousUser
[INFO] :: [12/07/2015 13:27:56] :: [views:select_login:info] [83] :: chargement de la page /profil/login par AnonymousUser
[INFO] :: [12/07/2015 13:27:56] :: [views:select_login:info] [83] :: chargement de la page /profil/login par AnonymousUser
[INFO] :: [12/07/2015 13:27:56] :: [views:select_login:info] [83] :: chargement de la page /profil/login par AnonymousUser
[INFO] :: [12/07/2015 13:27:56] :: [views:register_user:info] [28] :: chargement de la page /profil/register par AnonymousUser
[INFO] :: [12/07/2015 13:27:56] :: [views:register_user:info] [52] :: creation du compte AnonymousUser
[ERROR] :: [12/07/2015 13:27:56] :: [base:handle_uncaught_exception:django.request] [256] :: Internal Server Error: /profil/register
Traceback (most recent call last):
  File "D:\42_work\framework\venv\lib\site-packages\django\utils\datastructures.py", line 320, in __getitem__
    list_ = super(MultiValueDict, self).__getitem__(key)
KeyError: 'next'

During handling of the above exception, another exception occurred:

Traceback (most recent call last):
  File "D:\42_work\framework\venv\lib\site-packages\django\core\handlers\base.py", line 132, in get_response
    response = wrapped_callback(request, *callback_args, **callback_kwargs)
  File "D:\42_work\framework\app\profil\views.py", line 54, in register_user
    if request.GET['next'] != reverse('register'):
  File "D:\42_work\framework\venv\lib\site-packages\django\utils\datastructures.py", line 322, in __getitem__
    raise MultiValueDictKeyError(repr(key))
django.utils.datastructures.MultiValueDictKeyError: "'next'"
[INFO] :: [12/07/2015 13:27:56] :: [views:register_user:info] [28] :: chargement de la page /profil/register par AnonymousUser
[INFO] :: [12/07/2015 13:27:56] :: [views:register_user:info] [52] :: creation du compte AnonymousUser
[ERROR] :: [12/07/2015 13:27:56] :: [base:handle_uncaught_exception:django.request] [256] :: Internal Server Error: /profil/register
Traceback (most recent call last):
  File "D:\42_work\framework\venv\lib\site-packages\django\utils\datastructures.py", line 320, in __getitem__
    list_ = super(MultiValueDict, self).__getitem__(key)
KeyError: 'next'

During handling of the above exception, another exception occurred:

Traceback (most recent call last):
  File "D:\42_work\framework\venv\lib\site-packages\django\core\handlers\base.py", line 132, in get_response
    response = wrapped_callback(request, *callback_args, **callback_kwargs)
  File "D:\42_work\framework\app\profil\views.py", line 54, in register_user
    if request.GET['next'] != reverse('register'):
  File "D:\42_work\framework\venv\lib\site-packages\django\utils\datastructures.py", line 322, in __getitem__
    raise MultiValueDictKeyError(repr(key))
django.utils.datastructures.MultiValueDictKeyError: "'next'"
[INFO] :: [12/07/2015 13:27:56] :: [views:register_user:info] [28] :: chargement de la page /profil/register par AnonymousUser
[INFO] :: [12/07/2015 13:27:56] :: [views:register_user:info] [28] :: chargement de la page /profil/register par AnonymousUser
[INFO] :: [12/07/2015 13:27:56] :: [views:register_user:info] [28] :: chargement de la page /profil/register par AnonymousUser
[INFO] :: [12/07/2015 13:27:56] :: [views:register_user:info] [28] :: chargement de la page /profil/register par AnonymousUser
[INFO] :: [12/07/2015 15:10:06] :: [home:index:info] [13] :: chargement de la page / par admin
[INFO] :: [12/07/2015 15:10:39] :: [home:index:info] [13] :: chargement de la page / par admin
[ERROR] :: [12/07/2015 15:10:42] :: [base:handle_uncaught_exception:django.request] [256] :: Internal Server Error: /i18n/setlang
Traceback (most recent call last):
  File "D:\42_work\framework\venv\lib\site-packages\django\core\handlers\base.py", line 108, in get_response
    response = middleware_method(request)
  File "D:\42_work\framework\venv\lib\site-packages\django\middleware\common.py", line 84, in process_request
    "settings.") % (new_url[0], new_url[1]))
RuntimeError: You called this URL via POST, but the URL doesn't end in a slash and you have APPEND_SLASH set. Django can't redirect to the slash URL while maintaining POST data. Change your form to point to 127.0.0.1:8000/i18n/setlang/ (note the trailing slash), or set APPEND_SLASH=False in your Django settings.
[ERROR] :: [12/07/2015 15:11:15] :: [base:handle_uncaught_exception:django.request] [256] :: Internal Server Error: /i18n/setlang
Traceback (most recent call last):
  File "D:\42_work\framework\venv\lib\site-packages\django\core\handlers\base.py", line 108, in get_response
    response = middleware_method(request)
  File "D:\42_work\framework\venv\lib\site-packages\django\middleware\common.py", line 84, in process_request
    "settings.") % (new_url[0], new_url[1]))
RuntimeError: You called this URL via POST, but the URL doesn't end in a slash and you have APPEND_SLASH set. Django can't redirect to the slash URL while maintaining POST data. Change your form to point to 127.0.0.1:8000/i18n/setlang/ (note the trailing slash), or set APPEND_SLASH=False in your Django settings.
[INFO] :: [12/07/2015 15:11:18] :: [home:index:info] [13] :: chargement de la page / par admin
[ERROR] :: [12/07/2015 15:11:20] :: [base:handle_uncaught_exception:django.request] [256] :: Internal Server Error: /i18n/setlang
Traceback (most recent call last):
  File "D:\42_work\framework\venv\lib\site-packages\django\core\handlers\base.py", line 108, in get_response
    response = middleware_method(request)
  File "D:\42_work\framework\venv\lib\site-packages\django\middleware\common.py", line 84, in process_request
    "settings.") % (new_url[0], new_url[1]))
RuntimeError: You called this URL via POST, but the URL doesn't end in a slash and you have APPEND_SLASH set. Django can't redirect to the slash URL while maintaining POST data. Change your form to point to 127.0.0.1:8000/i18n/setlang/ (note the trailing slash), or set APPEND_SLASH=False in your Django settings.
[INFO] :: [12/07/2015 15:11:49] :: [home:index:info] [13] :: chargement de la page / par admin
[INFO] :: [12/07/2015 15:11:51] :: [home:index:info] [13] :: chargement de la page / par admin
[INFO] :: [12/07/2015 15:11:54] :: [home:index:info] [13] :: chargement de la page / par admin
[INFO] :: [12/07/2015 15:11:57] :: [home:index:info] [13] :: chargement de la page / par admin
[INFO] :: [12/07/2015 15:12:13] :: [home:index:info] [13] :: chargement de la page / par admin
[INFO] :: [12/07/2015 15:12:13] :: [home:index:info] [13] :: chargement de la page / par admin
[INFO] :: [12/07/2015 15:12:18] :: [home:index:info] [13] :: chargement de la page / par admin
[INFO] :: [12/07/2015 15:12:20] :: [home:index:info] [13] :: chargement de la page / par admin
[INFO] :: [12/07/2015 14:13:24] :: [home:index:info] [13] :: chargement de la page / par admin
[INFO] :: [12/07/2015 14:13:25] :: [home:index:info] [13] :: chargement de la page / par admin
[INFO] :: [12/07/2015 14:13:36] :: [home:index:info] [13] :: chargement de la page / par admin
[INFO] :: [12/07/2015 14:13:40] :: [home:index:info] [13] :: chargement de la page / par admin
[INFO] :: [12/07/2015 14:15:57] :: [home:index:info] [15] :: chargement de la page / par admin
[INFO] :: [12/07/2015 14:16:09] :: [home:index:info] [15] :: chargement de la page / par admin
[INFO] :: [12/07/2015 14:17:31] :: [home:index:info] [15] :: chargement de la page / par admin
[INFO] :: [12/07/2015 14:18:06] :: [home:index:info] [15] :: chargement de la page / par admin
[INFO] :: [12/07/2015 14:18:16] :: [home:index:info] [15] :: chargement de la page / par admin
[INFO] :: [12/07/2015 14:18:20] :: [home:index:info] [15] :: chargement de la page / par admin
[INFO] :: [12/07/2015 14:20:09] :: [home:index:info] [15] :: chargement de la page / par admin
[INFO] :: [12/07/2015 14:20:19] :: [home:index:info] [15] :: chargement de la page / par admin
[INFO] :: [12/07/2015 14:20:24] :: [views:index:info] [22] :: chargement de la page /issue/ par admin
[INFO] :: [12/07/2015 14:55:40] :: [home:index:info] [13] :: chargement de la page / par admin
[INFO] :: [12/07/2015 14:55:47] :: [home:index:info] [13] :: chargement de la page / par admin
[INFO] :: [12/07/2015 14:55:51] :: [home:index:info] [13] :: chargement de la page / par admin
[INFO] :: [12/07/2015 14:57:18] :: [home:index:info] [13] :: chargement de la page / par admin
[INFO] :: [12/07/2015 14:57:22] :: [home:index:info] [13] :: chargement de la page / par admin
[INFO] :: [12/07/2015 14:57:36] :: [views:index:info] [14] :: chargement de la page /log/ par admin
[INFO] :: [12/07/2015 14:57:39] :: [views:display_log:info] [25] :: chargement de la page /log/django/ par admin
[INFO] :: [12/07/2015 15:00:25] :: [views:index:info] [14] :: chargement de la page /log/ par admin
[INFO] :: [12/07/2015 15:00:28] :: [views:display_log:info] [25] :: chargement de la page /log/django/ par admin
[INFO] :: [12/07/2015 15:00:58] :: [views:display_log:info] [25] :: chargement de la page /log/django/ par admin
[INFO] :: [12/07/2015 15:01:01] :: [views:display_log:info] [25] :: chargement de la page /log/django/ par admin
[INFO] :: [12/07/2015 15:03:41] :: [views:display_log:info] [25] :: chargement de la page /log/django/ par admin
[INFO] :: [12/07/2015 15:04:20] :: [views:display_log:info] [25] :: chargement de la page /log/django/ par admin
[INFO] :: [12/07/2015 15:04:22] :: [views:index:info] [14] :: chargement de la page /log/ par admin
[INFO] :: [12/07/2015 15:04:25] :: [views:display_log:info] [25] :: chargement de la page /log/complet/ par admin
[INFO] :: [12/07/2015 15:04:37] :: [views:index:info] [14] :: chargement de la page /log/ par admin
[INFO] :: [12/07/2015 15:04:41] :: [views:display_log:info] [25] :: chargement de la page /log/error/ par admin
[INFO] :: [12/07/2015 15:04:43] :: [views:index:info] [14] :: chargement de la page /log/ par admin
[INFO] :: [12/07/2015 15:21:47] :: [home:index:info] [12] :: chargement de la page / par admin
[INFO] :: [12/07/2015 15:22:22] :: [views:logout_user:info] [212] :: chargement de la page /profil/logout par admin
[INFO] :: [12/07/2015 15:22:25] :: [home:index:info] [12] :: chargement de la page / par AnonymousUser
[INFO] :: [12/07/2015 15:22:28] :: [views:login_ldap:info] [154] :: chargement de la page /profil/ldap par AnonymousUser
[INFO] :: [12/07/2015 15:22:48] :: [views:login_ldap:info] [154] :: chargement de la page /profil/ldap par AnonymousUser
[INFO] :: [12/07/2015 15:22:52] :: [home:index:info] [12] :: chargement de la page / par AnonymousUser
[INFO] :: [12/07/2015 15:22:52] :: [views:login_ldap:info] [179] :: connection classique par AnonymousUser
[INFO] :: [12/07/2015 15:22:59] :: [views:login_user:info] [95] :: chargement de la page /profil/local par AnonymousUser
[INFO] :: [12/07/2015 15:23:05] :: [views:login_user:info] [95] :: chargement de la page /profil/local par AnonymousUser
[ERROR] :: [12/07/2015 15:23:05] :: [views:login_user:error] [104] :: un admin a essaye de se connecter depuis le front comme un boulet
[INFO] :: [12/07/2015 15:23:18] :: [home:index:info] [12] :: chargement de la page / par AnonymousUser
[INFO] :: [12/07/2015 15:23:29] :: [home:index:info] [12] :: chargement de la page / par admin
[INFO] :: [12/07/2015 15:23:31] :: [views:index:info] [14] :: chargement de la page /log/ par admin
[INFO] :: [12/07/2015 15:23:35] :: [views:display_log:info] [25] :: chargement de la page /log/error/ par admin
[INFO] :: [12/07/2015 15:23:40] :: [views:index:info] [14] :: chargement de la page /log/ par admin
[INFO] :: [12/07/2015 15:23:45] :: [views:display_log:info] [25] :: chargement de la page /log/complet/ par admin
[INFO] :: [12/07/2015 15:24:01] :: [views:logout_user:info] [212] :: chargement de la page /profil/logout par admin
[INFO] :: [12/07/2015 15:24:01] :: [views:select_login:info] [85] :: chargement de la page /profil/login par AnonymousUser
[WARNING] :: [12/07/2015 15:30:08] :: [base:get_response:django.request] [170] :: Not Found: /profil
[INFO] :: [12/07/2015 15:30:08] :: [views:login_ldap:info] [154] :: chargement de la page /profil/ldap par AnonymousUser
[INFO] :: [12/07/2015 15:30:09] :: [home:index:info] [12] :: chargement de la page / par AnonymousUser
[INFO] :: [12/07/2015 15:30:13] :: [views:login_ldap:info] [154] :: chargement de la page /profil/ldap par AnonymousUser
[INFO] :: [12/07/2015 15:30:23] :: [views:login_ldap:info] [154] :: chargement de la page /profil/ldap par AnonymousUser
[INFO] :: [12/07/2015 15:30:25] :: [views:login_ldap:info] [179] :: connection classique par AnonymousUser
[INFO] :: [12/07/2015 15:31:37] :: [views:login_ldap:info] [154] :: chargement de la page /profil/ldap par AnonymousUser
[INFO] :: [12/07/2015 15:31:40] :: [views:login_ldap:info] [179] :: connection classique par AnonymousUser
[ERROR] :: [12/07/2015 15:31:40] :: [base:handle_uncaught_exception:django.request] [256] :: Internal Server Error: /profil/ldap
Traceback (most recent call last):
  File "/home/chrysa/Bureau/42_work/framework/venv/lib/python3.4/site-packages/django/core/handlers/base.py", line 132, in get_response
    response = wrapped_callback(request, *callback_args, **callback_kwargs)
  File "/home/chrysa/Bureau/42_work/framework/app/profil/views.py", line 187, in login_ldap
    'objectClass',
  File "/home/chrysa/Bureau/42_work/framework/venv/lib/python3.4/site-packages/ldap3/core/connection.py", line 568, in search
    request = search_operation(search_base, search_filter, search_scope, dereference_aliases, attributes, size_limit, time_limit, types_only, self.server.schema if self.server else None)
  File "/home/chrysa/Bureau/42_work/framework/venv/lib/python3.4/site-packages/ldap3/operation/search.py", line 369, in search_operation
    request['attributes'] = build_attribute_selection(attributes, schema)
  File "/home/chrysa/Bureau/42_work/framework/venv/lib/python3.4/site-packages/ldap3/operation/search.py", line 324, in build_attribute_selection
    raise LDAPAttributeError('invalid attribute type in attribute list: ' + attribute)
ldap3.core.exceptions.LDAPAttributeError: invalid attribute type in attribute list: first-name
[INFO] :: [12/07/2015 15:32:29] :: [home:index:info] [12] :: chargement de la page / par AnonymousUser
[INFO] :: [12/07/2015 15:33:15] :: [home:index:info] [12] :: chargement de la page / par admin
[INFO] :: [12/07/2015 15:33:17] :: [views:index:info] [14] :: chargement de la page /log/ par admin
[INFO] :: [12/07/2015 15:33:19] :: [views:display_log:info] [25] :: chargement de la page /log/error/ par admin
[INFO] :: [12/07/2015 15:33:53] :: [views:display_log:info] [25] :: chargement de la page /log/error/ par admin
[INFO] :: [12/07/2015 15:34:07] :: [views:display_log:info] [25] :: chargement de la page /log/error/ par admin
[INFO] :: [12/07/2015 15:34:51] :: [views:display_log:info] [25] :: chargement de la page /log/error/ par admin
[ERROR] :: [12/07/2015 15:34:51] :: [base:handle_uncaught_exception:django.request] [256] :: Internal Server Error: /log/error/
Traceback (most recent call last):
  File "/home/chrysa/Bureau/42_work/framework/venv/lib/python3.4/site-packages/django/core/handlers/base.py", line 132, in get_response
    response = wrapped_callback(request, *callback_args, **callback_kwargs)
  File "/home/chrysa/Bureau/42_work/framework/venv/lib/python3.4/site-packages/django/contrib/auth/decorators.py", line 22, in _wrapped_view
    return view_func(request, *args, **kwargs)
  File "/home/chrysa/Bureau/42_work/framework/app/generate_logs/views.py", line 42, in display_log
    split_ligne[2] = split_ligne[2].replace('\n', '').split(' par ')
IndexError: list index out of range
[INFO] :: [12/07/2015 15:35:55] :: [views:display_log:info] [25] :: chargement de la page /log/error/ par admin
[ERROR] :: [12/07/2015 15:35:55] :: [base:handle_uncaught_exception:django.request] [256] :: Internal Server Error: /log/error/
Traceback (most recent call last):
  File "/home/chrysa/Bureau/42_work/framework/venv/lib/python3.4/site-packages/django/core/handlers/base.py", line 132, in get_response
    response = wrapped_callback(request, *callback_args, **callback_kwargs)
  File "/home/chrysa/Bureau/42_work/framework/venv/lib/python3.4/site-packages/django/contrib/auth/decorators.py", line 22, in _wrapped_view
    return view_func(request, *args, **kwargs)
  File "/home/chrysa/Bureau/42_work/framework/app/generate_logs/views.py", line 61, in display_log
    if add:
UnboundLocalError: local variable 'add' referenced before assignment
[INFO] :: [12/07/2015 15:36:19] :: [views:display_log:info] [25] :: chargement de la page /log/error/ par admin
[INFO] :: [12/07/2015 15:36:45] :: [views:display_log:info] [25] :: chargement de la page /log/error/ par admin
[ERROR] :: [12/07/2015 15:36:45] :: [base:handle_uncaught_exception:django.request] [256] :: Internal Server Error: /log/error/
Traceback (most recent call last):
  File "/home/chrysa/Bureau/42_work/framework/venv/lib/python3.4/site-packages/django/core/handlers/base.py", line 132, in get_response
    response = wrapped_callback(request, *callback_args, **callback_kwargs)
  File "/home/chrysa/Bureau/42_work/framework/venv/lib/python3.4/site-packages/django/contrib/auth/decorators.py", line 22, in _wrapped_view
    return view_func(request, *args, **kwargs)
  File "/home/chrysa/Bureau/42_work/framework/app/generate_logs/views.py", line 46, in display_log
    split_ligne.remove(split_ligne[4])
IndexError: list index out of range
[INFO] :: [12/07/2015 15:37:03] :: [views:display_log:info] [25] :: chargement de la page /log/error/ par admin
[INFO] :: [12/07/2015 15:37:14] :: [views:display_log:info] [25] :: chargement de la page /log/error/ par admin
[INFO] :: [12/07/2015 15:38:01] :: [views:display_log:info] [25] :: chargement de la page /log/error/ par admin
[INFO] :: [12/07/2015 15:39:06] :: [views:index:info] [14] :: chargement de la page /log/ par admin
[INFO] :: [12/07/2015 15:39:10] :: [views:display_log:info] [25] :: chargement de la page /log/info/ par admin
[INFO] :: [12/07/2015 15:39:40] :: [views:display_log:info] [25] :: chargement de la page /log/info/ par admin
[INFO] :: [12/07/2015 15:39:57] :: [views:display_log:info] [25] :: chargement de la page /log/info/ par admin
[INFO] :: [12/07/2015 15:40:24] :: [views:display_log:info] [25] :: chargement de la page /log/info/ par admin
[INFO] :: [12/07/2015 15:41:06] :: [views:display_log:info] [25] :: chargement de la page /log/info/ par admin
[INFO] :: [12/07/2015 15:41:32] :: [views:display_log:info] [25] :: chargement de la page /log/info/ par admin
[INFO] :: [12/07/2015 15:41:51] :: [views:display_log:info] [25] :: chargement de la page /log/info/ par admin
[INFO] :: [12/07/2015 15:42:34] :: [views:display_log:info] [25] :: chargement de la page /log/info/ par admin
[INFO] :: [12/07/2015 15:42:40] :: [views:display_log:info] [25] :: chargement de la page /log/info/ par admin
[INFO] :: [12/07/2015 15:42:42] :: [views:display_log:info] [25] :: chargement de la page /log/error/ par admin
