[10/07/2015 23:09:51] :: [base:handle_uncaught_exception:django.request] [256] :: Internal Server Error: /
Traceback (most recent call last):
  File "/home/chrysa/Bureau/42_work/framework/venv/lib/python3.4/site-packages/django/core/handlers/base.py", line 132, in get_response
    response = wrapped_callback(request, *callback_args, **callback_kwargs)
  File "/home/chrysa/Bureau/42_work/framework/app/core/home.py", line 12, in index
    logger.info(info_load_log_message(request))
  File "/home/chrysa/Bureau/42_work/framework/app/generate_logs/functions.py", line 5, in info_load_log_message
    return 'chargement de la page ' + request.META['PATH_INFO'] + ' par ' + request.user
TypeError: Can't convert 'SimpleLazyObject' object to str implicitly
[10/07/2015 23:10:11] :: [base:handle_uncaught_exception:django.request] [256] :: Internal Server Error: /
Traceback (most recent call last):
  File "/home/chrysa/Bureau/42_work/framework/venv/lib/python3.4/site-packages/django/core/handlers/base.py", line 132, in get_response
    response = wrapped_callback(request, *callback_args, **callback_kwargs)
  File "/home/chrysa/Bureau/42_work/framework/app/core/home.py", line 12, in index
    logger.info(info_load_log_message(request))
  File "/home/chrysa/Bureau/42_work/framework/app/generate_logs/functions.py", line 4, in info_load_log_message
    return 'chargement de la page ' + request.META['PATH_INFO'] + ' par ' + request.user
TypeError: Can't convert 'SimpleLazyObject' object to str implicitly
[10/07/2015 23:16:24] :: [base:handle_uncaught_exception:django.request] [256] :: Internal Server Error: /log/info/
Traceback (most recent call last):
  File "/home/chrysa/Bureau/42_work/framework/venv/lib/python3.4/site-packages/django/core/handlers/base.py", line 132, in get_response
    response = wrapped_callback(request, *callback_args, **callback_kwargs)
  File "/home/chrysa/Bureau/42_work/framework/venv/lib/python3.4/site-packages/django/contrib/auth/decorators.py", line 22, in _wrapped_view
    return view_func(request, *args, **kwargs)
  File "/home/chrysa/Bureau/42_work/framework/app/generate_logs/views.py", line 60, in display_log
    log.append(
AttributeError: 'NoneType' object has no attribute 'append'
[11/07/2015 20:27:36] :: [base:handle_uncaught_exception:django.request] [256] :: Internal Server Error: /profil/register
Traceback (most recent call last):
  File "/home/chrysa/Bureau/42_work/framework/venv/lib/python3.4/site-packages/django/utils/datastructures.py", line 320, in __getitem__
    list_ = super(MultiValueDict, self).__getitem__(key)
KeyError: 'next'

During handling of the above exception, another exception occurred:

Traceback (most recent call last):
  File "/home/chrysa/Bureau/42_work/framework/venv/lib/python3.4/site-packages/django/core/handlers/base.py", line 132, in get_response
    response = wrapped_callback(request, *callback_args, **callback_kwargs)
  File "/home/chrysa/Bureau/42_work/framework/app/profil/views.py", line 54, in register_user
    if request.GET['next'] != reverse('register'):
  File "/home/chrysa/Bureau/42_work/framework/venv/lib/python3.4/site-packages/django/utils/datastructures.py", line 322, in __getitem__
    raise MultiValueDictKeyError(repr(key))
django.utils.datastructures.MultiValueDictKeyError: "'next'"
[11/07/2015 20:27:36] :: [base:handle_uncaught_exception:django.request] [256] :: Internal Server Error: /profil/register
Traceback (most recent call last):
  File "/home/chrysa/Bureau/42_work/framework/venv/lib/python3.4/site-packages/django/utils/datastructures.py", line 320, in __getitem__
    list_ = super(MultiValueDict, self).__getitem__(key)
KeyError: 'next'

During handling of the above exception, another exception occurred:

Traceback (most recent call last):
  File "/home/chrysa/Bureau/42_work/framework/venv/lib/python3.4/site-packages/django/core/handlers/base.py", line 132, in get_response
    response = wrapped_callback(request, *callback_args, **callback_kwargs)
  File "/home/chrysa/Bureau/42_work/framework/app/profil/views.py", line 54, in register_user
    if request.GET['next'] != reverse('register'):
  File "/home/chrysa/Bureau/42_work/framework/venv/lib/python3.4/site-packages/django/utils/datastructures.py", line 322, in __getitem__
    raise MultiValueDictKeyError(repr(key))
django.utils.datastructures.MultiValueDictKeyError: "'next'"
[11/07/2015 20:28:08] :: [base:handle_uncaught_exception:django.request] [256] :: Internal Server Error: /profil/register
Traceback (most recent call last):
  File "/home/chrysa/Bureau/42_work/framework/venv/lib/python3.4/site-packages/django/utils/datastructures.py", line 320, in __getitem__
    list_ = super(MultiValueDict, self).__getitem__(key)
KeyError: 'next'

During handling of the above exception, another exception occurred:

Traceback (most recent call last):
  File "/home/chrysa/Bureau/42_work/framework/venv/lib/python3.4/site-packages/django/core/handlers/base.py", line 132, in get_response
    response = wrapped_callback(request, *callback_args, **callback_kwargs)
  File "/home/chrysa/Bureau/42_work/framework/app/profil/views.py", line 54, in register_user
    if request.GET['next'] != reverse('register'):
  File "/home/chrysa/Bureau/42_work/framework/venv/lib/python3.4/site-packages/django/utils/datastructures.py", line 322, in __getitem__
    raise MultiValueDictKeyError(repr(key))
django.utils.datastructures.MultiValueDictKeyError: "'next'"
[11/07/2015 20:28:08] :: [base:handle_uncaught_exception:django.request] [256] :: Internal Server Error: /profil/register
Traceback (most recent call last):
  File "/home/chrysa/Bureau/42_work/framework/venv/lib/python3.4/site-packages/django/utils/datastructures.py", line 320, in __getitem__
    list_ = super(MultiValueDict, self).__getitem__(key)
KeyError: 'next'

During handling of the above exception, another exception occurred:

Traceback (most recent call last):
  File "/home/chrysa/Bureau/42_work/framework/venv/lib/python3.4/site-packages/django/core/handlers/base.py", line 132, in get_response
    response = wrapped_callback(request, *callback_args, **callback_kwargs)
  File "/home/chrysa/Bureau/42_work/framework/app/profil/views.py", line 54, in register_user
    if request.GET['next'] != reverse('register'):
  File "/home/chrysa/Bureau/42_work/framework/venv/lib/python3.4/site-packages/django/utils/datastructures.py", line 322, in __getitem__
    raise MultiValueDictKeyError(repr(key))
django.utils.datastructures.MultiValueDictKeyError: "'next'"
[12/07/2015 14:24:06] :: [base:handle_uncaught_exception:django.request] [256] :: Internal Server Error: /profil/register
Traceback (most recent call last):
  File "D:\42_work\framework\venv\lib\site-packages\django\utils\datastructures.py", line 320, in __getitem__
    list_ = super(MultiValueDict, self).__getitem__(key)
KeyError: 'next'

During handling of the above exception, another exception occurred:

Traceback (most recent call last):
  File "D:\42_work\framework\venv\lib\site-packages\django\core\handlers\base.py", line 132, in get_response
    response = wrapped_callback(request, *callback_args, **callback_kwargs)
  File "D:\42_work\framework\app\profil\views.py", line 54, in register_user
    if request.GET['next'] != reverse('register'):
  File "D:\42_work\framework\venv\lib\site-packages\django\utils\datastructures.py", line 322, in __getitem__
    raise MultiValueDictKeyError(repr(key))
django.utils.datastructures.MultiValueDictKeyError: "'next'"
[12/07/2015 14:24:06] :: [base:handle_uncaught_exception:django.request] [256] :: Internal Server Error: /profil/register
Traceback (most recent call last):
  File "D:\42_work\framework\venv\lib\site-packages\django\utils\datastructures.py", line 320, in __getitem__
    list_ = super(MultiValueDict, self).__getitem__(key)
KeyError: 'next'

During handling of the above exception, another exception occurred:

Traceback (most recent call last):
  File "D:\42_work\framework\venv\lib\site-packages\django\core\handlers\base.py", line 132, in get_response
    response = wrapped_callback(request, *callback_args, **callback_kwargs)
  File "D:\42_work\framework\app\profil\views.py", line 54, in register_user
    if request.GET['next'] != reverse('register'):
  File "D:\42_work\framework\venv\lib\site-packages\django\utils\datastructures.py", line 322, in __getitem__
    raise MultiValueDictKeyError(repr(key))
django.utils.datastructures.MultiValueDictKeyError: "'next'"
[12/07/2015 14:24:12] :: [base:get_response:django.request] [170] :: Not Found: /favicon.ico
[12/07/2015 14:24:40] :: [base:handle_uncaught_exception:django.request] [256] :: Internal Server Error: /profil/register
Traceback (most recent call last):
  File "D:\42_work\framework\venv\lib\site-packages\django\utils\datastructures.py", line 320, in __getitem__
    list_ = super(MultiValueDict, self).__getitem__(key)
KeyError: 'next'

During handling of the above exception, another exception occurred:

Traceback (most recent call last):
  File "D:\42_work\framework\venv\lib\site-packages\django\core\handlers\base.py", line 132, in get_response
    response = wrapped_callback(request, *callback_args, **callback_kwargs)
  File "D:\42_work\framework\app\profil\views.py", line 54, in register_user
    if request.GET['next'] != reverse('register'):
  File "D:\42_work\framework\venv\lib\site-packages\django\utils\datastructures.py", line 322, in __getitem__
    raise MultiValueDictKeyError(repr(key))
django.utils.datastructures.MultiValueDictKeyError: "'next'"
[12/07/2015 14:24:40] :: [base:handle_uncaught_exception:django.request] [256] :: Internal Server Error: /profil/register
Traceback (most recent call last):
  File "D:\42_work\framework\venv\lib\site-packages\django\utils\datastructures.py", line 320, in __getitem__
    list_ = super(MultiValueDict, self).__getitem__(key)
KeyError: 'next'

During handling of the above exception, another exception occurred:

Traceback (most recent call last):
  File "D:\42_work\framework\venv\lib\site-packages\django\core\handlers\base.py", line 132, in get_response
    response = wrapped_callback(request, *callback_args, **callback_kwargs)
  File "D:\42_work\framework\app\profil\views.py", line 54, in register_user
    if request.GET['next'] != reverse('register'):
  File "D:\42_work\framework\venv\lib\site-packages\django\utils\datastructures.py", line 322, in __getitem__
    raise MultiValueDictKeyError(repr(key))
django.utils.datastructures.MultiValueDictKeyError: "'next'"
[12/07/2015 13:27:56] :: [base:handle_uncaught_exception:django.request] [256] :: Internal Server Error: /profil/register
Traceback (most recent call last):
  File "D:\42_work\framework\venv\lib\site-packages\django\utils\datastructures.py", line 320, in __getitem__
    list_ = super(MultiValueDict, self).__getitem__(key)
KeyError: 'next'

During handling of the above exception, another exception occurred:

Traceback (most recent call last):
  File "D:\42_work\framework\venv\lib\site-packages\django\core\handlers\base.py", line 132, in get_response
    response = wrapped_callback(request, *callback_args, **callback_kwargs)
  File "D:\42_work\framework\app\profil\views.py", line 54, in register_user
    if request.GET['next'] != reverse('register'):
  File "D:\42_work\framework\venv\lib\site-packages\django\utils\datastructures.py", line 322, in __getitem__
    raise MultiValueDictKeyError(repr(key))
django.utils.datastructures.MultiValueDictKeyError: "'next'"
[12/07/2015 13:27:56] :: [base:handle_uncaught_exception:django.request] [256] :: Internal Server Error: /profil/register
Traceback (most recent call last):
  File "D:\42_work\framework\venv\lib\site-packages\django\utils\datastructures.py", line 320, in __getitem__
    list_ = super(MultiValueDict, self).__getitem__(key)
KeyError: 'next'

During handling of the above exception, another exception occurred:

Traceback (most recent call last):
  File "D:\42_work\framework\venv\lib\site-packages\django\core\handlers\base.py", line 132, in get_response
    response = wrapped_callback(request, *callback_args, **callback_kwargs)
  File "D:\42_work\framework\app\profil\views.py", line 54, in register_user
    if request.GET['next'] != reverse('register'):
  File "D:\42_work\framework\venv\lib\site-packages\django\utils\datastructures.py", line 322, in __getitem__
    raise MultiValueDictKeyError(repr(key))
django.utils.datastructures.MultiValueDictKeyError: "'next'"
[12/07/2015 15:10:42] :: [base:handle_uncaught_exception:django.request] [256] :: Internal Server Error: /i18n/setlang
Traceback (most recent call last):
  File "D:\42_work\framework\venv\lib\site-packages\django\core\handlers\base.py", line 108, in get_response
    response = middleware_method(request)
  File "D:\42_work\framework\venv\lib\site-packages\django\middleware\common.py", line 84, in process_request
    "settings.") % (new_url[0], new_url[1]))
RuntimeError: You called this URL via POST, but the URL doesn't end in a slash and you have APPEND_SLASH set. Django can't redirect to the slash URL while maintaining POST data. Change your form to point to 127.0.0.1:8000/i18n/setlang/ (note the trailing slash), or set APPEND_SLASH=False in your Django settings.
[12/07/2015 15:11:15] :: [base:handle_uncaught_exception:django.request] [256] :: Internal Server Error: /i18n/setlang
Traceback (most recent call last):
  File "D:\42_work\framework\venv\lib\site-packages\django\core\handlers\base.py", line 108, in get_response
    response = middleware_method(request)
  File "D:\42_work\framework\venv\lib\site-packages\django\middleware\common.py", line 84, in process_request
    "settings.") % (new_url[0], new_url[1]))
RuntimeError: You called this URL via POST, but the URL doesn't end in a slash and you have APPEND_SLASH set. Django can't redirect to the slash URL while maintaining POST data. Change your form to point to 127.0.0.1:8000/i18n/setlang/ (note the trailing slash), or set APPEND_SLASH=False in your Django settings.
[12/07/2015 15:11:20] :: [base:handle_uncaught_exception:django.request] [256] :: Internal Server Error: /i18n/setlang
Traceback (most recent call last):
  File "D:\42_work\framework\venv\lib\site-packages\django\core\handlers\base.py", line 108, in get_response
    response = middleware_method(request)
  File "D:\42_work\framework\venv\lib\site-packages\django\middleware\common.py", line 84, in process_request
    "settings.") % (new_url[0], new_url[1]))
RuntimeError: You called this URL via POST, but the URL doesn't end in a slash and you have APPEND_SLASH set. Django can't redirect to the slash URL while maintaining POST data. Change your form to point to 127.0.0.1:8000/i18n/setlang/ (note the trailing slash), or set APPEND_SLASH=False in your Django settings.
