[15/07/2015 11:10:22] :: [base:handle_uncaught_exception:django.request] [256] :: Internal Server Error: /profil/register
Traceback (most recent call last):
  File "/home/chrysa/Bureau/42_work/framework/venv/lib/python3.4/site-packages/django/utils/datastructures.py", line 320, in __getitem__
    list_ = super(MultiValueDict, self).__getitem__(key)
KeyError: 'password_conf'

During handling of the above exception, another exception occurred:

Traceback (most recent call last):
  File "/home/chrysa/Bureau/42_work/framework/venv/lib/python3.4/site-packages/django/core/handlers/base.py", line 132, in get_response
    response = wrapped_callback(request, *callback_args, **callback_kwargs)
  File "/home/chrysa/Bureau/42_work/framework/app/profil/views.py", line 43, in register_user
    if request.POST['password'] != request.POST['password_conf']:
  File "/home/chrysa/Bureau/42_work/framework/venv/lib/python3.4/site-packages/django/utils/datastructures.py", line 322, in __getitem__
    raise MultiValueDictKeyError(repr(key))
django.utils.datastructures.MultiValueDictKeyError: "'password_conf'"
[15/07/2015 11:11:11] :: [base:handle_uncaught_exception:django.request] [256] :: Internal Server Error: /profil/register
Traceback (most recent call last):
  File "/home/chrysa/Bureau/42_work/framework/venv/lib/python3.4/site-packages/django/utils/datastructures.py", line 320, in __getitem__
    list_ = super(MultiValueDict, self).__getitem__(key)
KeyError: 'password_conf'

During handling of the above exception, another exception occurred:

Traceback (most recent call last):
  File "/home/chrysa/Bureau/42_work/framework/venv/lib/python3.4/site-packages/django/core/handlers/base.py", line 132, in get_response
    response = wrapped_callback(request, *callback_args, **callback_kwargs)
  File "/home/chrysa/Bureau/42_work/framework/app/profil/views.py", line 43, in register_user
    if request.POST['password'] != request.POST['password_conf']:
  File "/home/chrysa/Bureau/42_work/framework/venv/lib/python3.4/site-packages/django/utils/datastructures.py", line 322, in __getitem__
    raise MultiValueDictKeyError(repr(key))
django.utils.datastructures.MultiValueDictKeyError: "'password_conf'"
[15/07/2015 11:11:30] :: [base:handle_uncaught_exception:django.request] [256] :: Internal Server Error: /profil/register
Traceback (most recent call last):
  File "/home/chrysa/Bureau/42_work/framework/venv/lib/python3.4/site-packages/django/utils/datastructures.py", line 320, in __getitem__
    list_ = super(MultiValueDict, self).__getitem__(key)
KeyError: 'password_conf'

During handling of the above exception, another exception occurred:

Traceback (most recent call last):
  File "/home/chrysa/Bureau/42_work/framework/venv/lib/python3.4/site-packages/django/core/handlers/base.py", line 132, in get_response
    response = wrapped_callback(request, *callback_args, **callback_kwargs)
  File "/home/chrysa/Bureau/42_work/framework/app/profil/views.py", line 43, in register_user
    if request.POST['password'] != request.POST['password_conf']:
  File "/home/chrysa/Bureau/42_work/framework/venv/lib/python3.4/site-packages/django/utils/datastructures.py", line 322, in __getitem__
    raise MultiValueDictKeyError(repr(key))
django.utils.datastructures.MultiValueDictKeyError: "'password_conf'"
[15/07/2015 11:12:41] :: [base:handle_uncaught_exception:django.request] [256] :: Internal Server Error: /profil/register
Traceback (most recent call last):
  File "/home/chrysa/Bureau/42_work/framework/venv/lib/python3.4/site-packages/django/utils/datastructures.py", line 320, in __getitem__
    list_ = super(MultiValueDict, self).__getitem__(key)
KeyError: 'password_conf'

During handling of the above exception, another exception occurred:

Traceback (most recent call last):
  File "/home/chrysa/Bureau/42_work/framework/venv/lib/python3.4/site-packages/django/core/handlers/base.py", line 132, in get_response
    response = wrapped_callback(request, *callback_args, **callback_kwargs)
  File "/home/chrysa/Bureau/42_work/framework/app/profil/views.py", line 43, in register_user
    if request.POST['password'] != request.POST['password_conf']:
  File "/home/chrysa/Bureau/42_work/framework/venv/lib/python3.4/site-packages/django/utils/datastructures.py", line 322, in __getitem__
    raise MultiValueDictKeyError(repr(key))
django.utils.datastructures.MultiValueDictKeyError: "'password_conf'"
[15/07/2015 13:18:17] :: [base:handle_uncaught_exception:django.request] [256] :: Internal Server Error: /profil/local
Traceback (most recent call last):
  File "/home/chrysa/Bureau/42_work/framework/venv/lib/python3.4/site-packages/django/core/handlers/base.py", line 132, in get_response
    response = wrapped_callback(request, *callback_args, **callback_kwargs)
  File "/home/chrysa/Bureau/42_work/framework/app/profil/views.py", line 120, in login_user
    if 'user' not in error:
NameError: name 'error' is not defined
[15/07/2015 13:18:35] :: [base:handle_uncaught_exception:django.request] [256] :: Internal Server Error: /profil/local
Traceback (most recent call last):
  File "/home/chrysa/Bureau/42_work/framework/venv/lib/python3.4/site-packages/django/core/handlers/base.py", line 132, in get_response
    response = wrapped_callback(request, *callback_args, **callback_kwargs)
  File "/home/chrysa/Bureau/42_work/framework/app/profil/views.py", line 120, in login_user
    if 'user' not in error:
NameError: name 'error' is not defined
[15/07/2015 13:19:05] :: [base:handle_uncaught_exception:django.request] [256] :: Internal Server Error: /profil/local
Traceback (most recent call last):
  File "/home/chrysa/Bureau/42_work/framework/venv/lib/python3.4/site-packages/django/core/handlers/base.py", line 132, in get_response
    response = wrapped_callback(request, *callback_args, **callback_kwargs)
  File "/home/chrysa/Bureau/42_work/framework/app/profil/views.py", line 118, in login_user
    if 'user' not in error:
NameError: name 'error' is not defined
[15/07/2015 13:19:46] :: [base:handle_uncaught_exception:django.request] [256] :: Internal Server Error: /profil/local
Traceback (most recent call last):
  File "/home/chrysa/Bureau/42_work/framework/venv/lib/python3.4/site-packages/django/utils/datastructures.py", line 320, in __getitem__
    list_ = super(MultiValueDict, self).__getitem__(key)
KeyError: 'next'

During handling of the above exception, another exception occurred:

Traceback (most recent call last):
  File "/home/chrysa/Bureau/42_work/framework/venv/lib/python3.4/site-packages/django/core/handlers/base.py", line 132, in get_response
    response = wrapped_callback(request, *callback_args, **callback_kwargs)
  File "/home/chrysa/Bureau/42_work/framework/app/profil/views.py", line 130, in login_user
    if request.GET['next'] != reverse('login_classic') or request.GET['next'] != reverse('login_ldap') or request.GET['next'] != reverse('login'):
  File "/home/chrysa/Bureau/42_work/framework/venv/lib/python3.4/site-packages/django/utils/datastructures.py", line 322, in __getitem__
    raise MultiValueDictKeyError(repr(key))
django.utils.datastructures.MultiValueDictKeyError: "'next'"
[15/07/2015 18:45:02] :: [base:get_response:django.request] [170] :: Not Found: /favicon.ico
[16/07/2015 00:53:21] :: [base:handle_uncaught_exception:django.request] [256] :: Internal Server Error: /profil/local
Traceback (most recent call last):
  File "D:\42_work\framework\venv\lib\site-packages\django\core\handlers\base.py", line 132, in get_response
    response = wrapped_callback(request, *callback_args, **callback_kwargs)
  File "D:\42_work\framework\app\profil\views.py", line 133, in login_user
    for k, v in request.user:
TypeError: 'User' object is not iterable
[16/07/2015 00:53:43] :: [csrf:_reject:django.request] [98] :: Forbidden (CSRF token missing or incorrect.): /profil/local
[16/07/2015 00:53:49] :: [base:handle_uncaught_exception:django.request] [256] :: Internal Server Error: /profil/local
Traceback (most recent call last):
  File "D:\42_work\framework\venv\lib\site-packages\django\core\handlers\base.py", line 132, in get_response
    response = wrapped_callback(request, *callback_args, **callback_kwargs)
  File "D:\42_work\framework\app\profil\views.py", line 132, in login_user
    print (request.user.items)
AttributeError: 'User' object has no attribute 'items'
[16/07/2015 00:54:15] :: [csrf:_reject:django.request] [98] :: Forbidden (CSRF token missing or incorrect.): /profil/local
[16/07/2015 02:00:15] :: [base:handle_uncaught_exception:django.request] [256] :: Internal Server Error: /profil/ldap
Traceback (most recent call last):
  File "D:\42_work\framework\venv\lib\site-packages\django\core\handlers\base.py", line 223, in get_response
    response = middleware_method(request, response)
  File "D:\42_work\framework\venv\lib\site-packages\django\contrib\sessions\middleware.py", line 50, in process_response
    request.session.save()
  File "D:\42_work\framework\venv\lib\site-packages\django\contrib\sessions\backends\db.py", line 58, in save
    session_data=self.encode(self._get_session(no_load=must_create)),
  File "D:\42_work\framework\venv\lib\site-packages\django\contrib\sessions\backends\base.py", line 88, in encode
    serialized = self.serializer().dumps(session_dict)
  File "D:\42_work\framework\venv\lib\site-packages\django\core\signing.py", line 90, in dumps
    return json.dumps(obj, separators=(',', ':')).encode('latin-1')
  File "C:\Python34\Lib\json\__init__.py", line 237, in dumps
    **kw).encode(obj)
  File "C:\Python34\Lib\json\encoder.py", line 192, in encode
    chunks = self.iterencode(o, _one_shot=True)
  File "C:\Python34\Lib\json\encoder.py", line 250, in iterencode
    return _iterencode(o, 0)
  File "C:\Python34\Lib\json\encoder.py", line 173, in default
    raise TypeError(repr(o) + " is not JSON serializable")
TypeError: <SimpleLazyObject: <django.contrib.auth.models.AnonymousUser object at 0x000000000477DDA0>> is not JSON serializable
[16/07/2015 02:28:32] :: [base:handle_uncaught_exception:django.request] [256] :: Internal Server Error: /profil/ldap
Traceback (most recent call last):
  File "D:\42_work\framework\venv\lib\site-packages\django\core\handlers\base.py", line 132, in get_response
    response = wrapped_callback(request, *callback_args, **callback_kwargs)
  File "D:\42_work\framework\app\profil\views.py", line 207, in login_ldap
    response[0]['attributes']['email'][0],
  File "D:\42_work\framework\venv\lib\site-packages\ldap3\utils\ciDict.py", line 67, in __getitem__
    return self._store[self._getkey(key)]
KeyError: 'email'
[16/07/2015 02:28:43] :: [base:handle_uncaught_exception:django.request] [256] :: Internal Server Error: /profil/ldap
Traceback (most recent call last):
  File "D:\42_work\framework\venv\lib\site-packages\django\core\handlers\base.py", line 132, in get_response
    response = wrapped_callback(request, *callback_args, **callback_kwargs)
  File "D:\42_work\framework\app\profil\views.py", line 207, in login_ldap
    response[0]['attributes']['email'][0],
  File "D:\42_work\framework\venv\lib\site-packages\ldap3\utils\ciDict.py", line 67, in __getitem__
    return self._store[self._getkey(key)]
KeyError: 'email'
[16/07/2015 02:29:32] :: [base:handle_uncaught_exception:django.request] [256] :: Internal Server Error: /profil/ldap
Traceback (most recent call last):
  File "D:\42_work\framework\venv\lib\site-packages\django\utils\datastructures.py", line 320, in __getitem__
    list_ = super(MultiValueDict, self).__getitem__(key)
KeyError: 'username'

During handling of the above exception, another exception occurred:

Traceback (most recent call last):
  File "D:\42_work\framework\venv\lib\site-packages\django\core\handlers\base.py", line 132, in get_response
    response = wrapped_callback(request, *callback_args, **callback_kwargs)
  File "D:\42_work\framework\app\profil\views.py", line 214, in login_ldap
    username=request.POST['username'],
  File "D:\42_work\framework\venv\lib\site-packages\django\utils\datastructures.py", line 322, in __getitem__
    raise MultiValueDictKeyError(repr(key))
django.utils.datastructures.MultiValueDictKeyError: "'username'"
[16/07/2015 02:30:14] :: [base:handle_uncaught_exception:django.request] [256] :: Internal Server Error: /profil/ldap
Traceback (most recent call last):
  File "D:\42_work\framework\venv\lib\site-packages\django\core\handlers\base.py", line 132, in get_response
    response = wrapped_callback(request, *callback_args, **callback_kwargs)
  File "D:\42_work\framework\app\profil\views.py", line 211, in login_ldap
    u.set_password(request.POST['password']).save()
AttributeError: 'QuerySet' object has no attribute 'set_password'
[16/07/2015 02:30:46] :: [base:handle_uncaught_exception:django.request] [256] :: Internal Server Error: /profil/ldap
Traceback (most recent call last):
  File "D:\42_work\framework\venv\lib\site-packages\django\db\backends\utils.py", line 64, in execute
    return self.cursor.execute(sql, params)
  File "D:\42_work\framework\venv\lib\site-packages\django\db\backends\sqlite3\base.py", line 318, in execute
    return Database.Cursor.execute(self, query, params)
sqlite3.IntegrityError: UNIQUE constraint failed: auth_user.username

The above exception was the direct cause of the following exception:

Traceback (most recent call last):
  File "D:\42_work\framework\venv\lib\site-packages\django\core\handlers\base.py", line 132, in get_response
    response = wrapped_callback(request, *callback_args, **callback_kwargs)
  File "D:\42_work\framework\app\profil\views.py", line 208, in login_ldap
    request.POST['password']
  File "D:\42_work\framework\app\profil\functions.py", line 18, in create_user
    password=password
  File "D:\42_work\framework\venv\lib\site-packages\django\contrib\auth\models.py", line 187, in create_user
    **extra_fields)
  File "D:\42_work\framework\venv\lib\site-packages\django\contrib\auth\models.py", line 182, in _create_user
    user.save(using=self._db)
  File "D:\42_work\framework\venv\lib\site-packages\django\db\models\base.py", line 710, in save
    force_update=force_update, update_fields=update_fields)
  File "D:\42_work\framework\venv\lib\site-packages\django\db\models\base.py", line 738, in save_base
    updated = self._save_table(raw, cls, force_insert, force_update, using, update_fields)
  File "D:\42_work\framework\venv\lib\site-packages\django\db\models\base.py", line 822, in _save_table
    result = self._do_insert(cls._base_manager, using, fields, update_pk, raw)
  File "D:\42_work\framework\venv\lib\site-packages\django\db\models\base.py", line 861, in _do_insert
    using=using, raw=raw)
  File "D:\42_work\framework\venv\lib\site-packages\django\db\models\manager.py", line 127, in manager_method
    return getattr(self.get_queryset(), name)(*args, **kwargs)
  File "D:\42_work\framework\venv\lib\site-packages\django\db\models\query.py", line 920, in _insert
    return query.get_compiler(using=using).execute_sql(return_id)
  File "D:\42_work\framework\venv\lib\site-packages\django\db\models\sql\compiler.py", line 974, in execute_sql
    cursor.execute(sql, params)
  File "D:\42_work\framework\venv\lib\site-packages\django\db\backends\utils.py", line 79, in execute
    return super(CursorDebugWrapper, self).execute(sql, params)
  File "D:\42_work\framework\venv\lib\site-packages\django\db\backends\utils.py", line 64, in execute
    return self.cursor.execute(sql, params)
  File "D:\42_work\framework\venv\lib\site-packages\django\db\utils.py", line 97, in __exit__
    six.reraise(dj_exc_type, dj_exc_value, traceback)
  File "D:\42_work\framework\venv\lib\site-packages\django\utils\six.py", line 658, in reraise
    raise value.with_traceback(tb)
  File "D:\42_work\framework\venv\lib\site-packages\django\db\backends\utils.py", line 64, in execute
    return self.cursor.execute(sql, params)
  File "D:\42_work\framework\venv\lib\site-packages\django\db\backends\sqlite3\base.py", line 318, in execute
    return Database.Cursor.execute(self, query, params)
django.db.utils.IntegrityError: UNIQUE constraint failed: auth_user.username
[16/07/2015 02:31:21] :: [base:handle_uncaught_exception:django.request] [256] :: Internal Server Error: /profil/ldap
Traceback (most recent call last):
  File "D:\42_work\framework\venv\lib\site-packages\django\db\backends\utils.py", line 64, in execute
    return self.cursor.execute(sql, params)
  File "D:\42_work\framework\venv\lib\site-packages\django\db\backends\sqlite3\base.py", line 318, in execute
    return Database.Cursor.execute(self, query, params)
sqlite3.IntegrityError: UNIQUE constraint failed: auth_user.username

The above exception was the direct cause of the following exception:

Traceback (most recent call last):
  File "D:\42_work\framework\venv\lib\site-packages\django\core\handlers\base.py", line 132, in get_response
    response = wrapped_callback(request, *callback_args, **callback_kwargs)
  File "D:\42_work\framework\app\profil\views.py", line 208, in login_ldap
    request.POST['password']
  File "D:\42_work\framework\app\profil\functions.py", line 18, in create_user
    password=password
  File "D:\42_work\framework\venv\lib\site-packages\django\contrib\auth\models.py", line 187, in create_user
    **extra_fields)
  File "D:\42_work\framework\venv\lib\site-packages\django\contrib\auth\models.py", line 182, in _create_user
    user.save(using=self._db)
  File "D:\42_work\framework\venv\lib\site-packages\django\db\models\base.py", line 710, in save
    force_update=force_update, update_fields=update_fields)
  File "D:\42_work\framework\venv\lib\site-packages\django\db\models\base.py", line 738, in save_base
    updated = self._save_table(raw, cls, force_insert, force_update, using, update_fields)
  File "D:\42_work\framework\venv\lib\site-packages\django\db\models\base.py", line 822, in _save_table
    result = self._do_insert(cls._base_manager, using, fields, update_pk, raw)
  File "D:\42_work\framework\venv\lib\site-packages\django\db\models\base.py", line 861, in _do_insert
    using=using, raw=raw)
  File "D:\42_work\framework\venv\lib\site-packages\django\db\models\manager.py", line 127, in manager_method
    return getattr(self.get_queryset(), name)(*args, **kwargs)
  File "D:\42_work\framework\venv\lib\site-packages\django\db\models\query.py", line 920, in _insert
    return query.get_compiler(using=using).execute_sql(return_id)
  File "D:\42_work\framework\venv\lib\site-packages\django\db\models\sql\compiler.py", line 974, in execute_sql
    cursor.execute(sql, params)
  File "D:\42_work\framework\venv\lib\site-packages\django\db\backends\utils.py", line 79, in execute
    return super(CursorDebugWrapper, self).execute(sql, params)
  File "D:\42_work\framework\venv\lib\site-packages\django\db\backends\utils.py", line 64, in execute
    return self.cursor.execute(sql, params)
  File "D:\42_work\framework\venv\lib\site-packages\django\db\utils.py", line 97, in __exit__
    six.reraise(dj_exc_type, dj_exc_value, traceback)
  File "D:\42_work\framework\venv\lib\site-packages\django\utils\six.py", line 658, in reraise
    raise value.with_traceback(tb)
  File "D:\42_work\framework\venv\lib\site-packages\django\db\backends\utils.py", line 64, in execute
    return self.cursor.execute(sql, params)
  File "D:\42_work\framework\venv\lib\site-packages\django\db\backends\sqlite3\base.py", line 318, in execute
    return Database.Cursor.execute(self, query, params)
django.db.utils.IntegrityError: UNIQUE constraint failed: auth_user.username
[16/07/2015 02:32:20] :: [base:handle_uncaught_exception:django.request] [256] :: Internal Server Error: /profil/ldap
Traceback (most recent call last):
  File "D:\42_work\framework\venv\lib\site-packages\django\core\handlers\base.py", line 132, in get_response
    response = wrapped_callback(request, *callback_args, **callback_kwargs)
  File "D:\42_work\framework\app\profil\views.py", line 211, in login_ldap
    u.set_password(request.POST['password']).save()
AttributeError: 'NoneType' object has no attribute 'save'
[16/07/2015 02:33:47] :: [base:handle_uncaught_exception:django.request] [256] :: Internal Server Error: /profil/ldap
Traceback (most recent call last):
  File "D:\42_work\framework\venv\lib\site-packages\django\core\handlers\base.py", line 132, in get_response
    response = wrapped_callback(request, *callback_args, **callback_kwargs)
  File "D:\42_work\framework\app\profil\views.py", line 204, in login_ldap
    print (len(u))
TypeError: object of type 'User' has no len()
[16/07/2015 02:35:02] :: [base:handle_uncaught_exception:django.request] [256] :: Internal Server Error: /profil/ldap
Traceback (most recent call last):
  File "D:\42_work\framework\venv\lib\site-packages\django\core\handlers\base.py", line 132, in get_response
    response = wrapped_callback(request, *callback_args, **callback_kwargs)
  File "D:\42_work\framework\app\profil\views.py", line 202, in login_ldap
    u = User.objects.get(username=response[0]['attributes']['uid'][0])
  File "D:\42_work\framework\venv\lib\site-packages\django\db\models\manager.py", line 127, in manager_method
    return getattr(self.get_queryset(), name)(*args, **kwargs)
  File "D:\42_work\framework\venv\lib\site-packages\django\db\models\query.py", line 334, in get
    self.model._meta.object_name
django.contrib.auth.models.DoesNotExist: User matching query does not exist.
[16/07/2015 02:36:03] :: [base:handle_uncaught_exception:django.request] [256] :: Internal Server Error: /profil/ldap
Traceback (most recent call last):
  File "D:\42_work\framework\venv\lib\site-packages\django\core\handlers\base.py", line 132, in get_response
    response = wrapped_callback(request, *callback_args, **callback_kwargs)
  File "D:\42_work\framework\app\profil\views.py", line 202, in login_ldap
    u = User.objects.get(username=response[0]['attributes']['uid'][0])
  File "D:\42_work\framework\venv\lib\site-packages\django\db\models\manager.py", line 127, in manager_method
    return getattr(self.get_queryset(), name)(*args, **kwargs)
  File "D:\42_work\framework\venv\lib\site-packages\django\db\models\query.py", line 334, in get
    self.model._meta.object_name
django.contrib.auth.models.DoesNotExist: User matching query does not exist.
[16/07/2015 02:36:51] :: [base:handle_uncaught_exception:django.request] [256] :: Internal Server Error: /profil/ldap
Traceback (most recent call last):
  File "D:\42_work\framework\venv\lib\site-packages\django\core\handlers\base.py", line 132, in get_response
    response = wrapped_callback(request, *callback_args, **callback_kwargs)
  File "D:\42_work\framework\app\profil\views.py", line 213, in login_ldap
    u[0].set_password(request.POST['password']).save()
  File "D:\42_work\framework\venv\lib\site-packages\django\db\models\query.py", line 184, in __getitem__
    return self._result_cache[k]
IndexError: list index out of range
[16/07/2015 02:43:02] :: [base:handle_uncaught_exception:django.request] [256] :: Internal Server Error: /
Traceback (most recent call last):
  File "D:\42_work\framework\venv\lib\site-packages\django\core\handlers\base.py", line 132, in get_response
    response = wrapped_callback(request, *callback_args, **callback_kwargs)
  File "D:\42_work\framework\app\core\home.py", line 13, in index
    return render(request, 'core/home.html', {})
  File "D:\42_work\framework\venv\lib\site-packages\django\shortcuts.py", line 67, in render
    template_name, context, request=request, using=using)
  File "D:\42_work\framework\venv\lib\site-packages\django\template\loader.py", line 99, in render_to_string
    return template.render(context, request)
  File "D:\42_work\framework\venv\lib\site-packages\django\template\backends\django.py", line 74, in render
    return self.template.render(context)
  File "D:\42_work\framework\venv\lib\site-packages\django\template\base.py", line 209, in render
    return self._render(context)
  File "D:\42_work\framework\venv\lib\site-packages\django\template\base.py", line 201, in _render
    return self.nodelist.render(context)
  File "D:\42_work\framework\venv\lib\site-packages\django\template\base.py", line 903, in render
    bit = self.render_node(node, context)
  File "D:\42_work\framework\venv\lib\site-packages\django\template\debug.py", line 79, in render_node
    return node.render(context)
  File "D:\42_work\framework\venv\lib\site-packages\django\template\loader_tags.py", line 113, in render
    compiled_parent = self.get_parent(context)
  File "D:\42_work\framework\venv\lib\site-packages\django\template\loader_tags.py", line 110, in get_parent
    return context.template.engine.get_template(parent)
  File "D:\42_work\framework\venv\lib\site-packages\django\template\engine.py", line 167, in get_template
    template, origin = self.find_template(template_name, dirs)
  File "D:\42_work\framework\venv\lib\site-packages\django\template\engine.py", line 141, in find_template
    source, display_name = loader(name, dirs)
  File "D:\42_work\framework\venv\lib\site-packages\django\template\loaders\base.py", line 13, in __call__
    return self.load_template(template_name, template_dirs)
  File "D:\42_work\framework\venv\lib\site-packages\django\template\loaders\base.py", line 23, in load_template
    template = Template(source, origin, template_name, self.engine)
  File "D:\42_work\framework\venv\lib\site-packages\django\template\base.py", line 190, in __init__
    self.nodelist = engine.compile_string(template_string, origin)
  File "D:\42_work\framework\venv\lib\site-packages\django\template\engine.py", line 261, in compile_string
    return parser.parse()
  File "D:\42_work\framework\venv\lib\site-packages\django\template\base.py", line 341, in parse
    compiled_result = compile_func(self, token)
  File "D:\42_work\framework\venv\lib\site-packages\django\template\defaulttags.py", line 1332, in spaceless
    nodelist = parser.parse(('endspaceless',))
  File "D:\42_work\framework\venv\lib\site-packages\django\template\base.py", line 317, in parse
    filter_expression = self.compile_filter(token.contents)
  File "D:\42_work\framework\venv\lib\site-packages\django\template\base.py", line 423, in compile_filter
    return FilterExpression(token, self)
  File "D:\42_work\framework\venv\lib\site-packages\django\template\base.py", line 639, in __init__
    "from '%s'" % (token[upto:], token))
django.template.base.TemplateSyntaxError: Could not parse the remainder: ',ldap' from 'request.session,ldap'
[16/07/2015 02:48:44] :: [base:handle_uncaught_exception:django.request] [256] :: Internal Server Error: /
Traceback (most recent call last):
  File "D:\42_work\framework\venv\lib\site-packages\django\template\smartif.py", line 177, in translate_token
    op = OPERATORS[token]
KeyError: '(url_forum'

During handling of the above exception, another exception occurred:

Traceback (most recent call last):
  File "D:\42_work\framework\venv\lib\site-packages\django\core\handlers\base.py", line 132, in get_response
    response = wrapped_callback(request, *callback_args, **callback_kwargs)
  File "D:\42_work\framework\app\core\home.py", line 13, in index
    return render(request, 'core/home.html', {})
  File "D:\42_work\framework\venv\lib\site-packages\django\shortcuts.py", line 67, in render
    template_name, context, request=request, using=using)
  File "D:\42_work\framework\venv\lib\site-packages\django\template\loader.py", line 99, in render_to_string
    return template.render(context, request)
  File "D:\42_work\framework\venv\lib\site-packages\django\template\backends\django.py", line 74, in render
    return self.template.render(context)
  File "D:\42_work\framework\venv\lib\site-packages\django\template\base.py", line 209, in render
    return self._render(context)
  File "D:\42_work\framework\venv\lib\site-packages\django\template\base.py", line 201, in _render
    return self.nodelist.render(context)
  File "D:\42_work\framework\venv\lib\site-packages\django\template\base.py", line 903, in render
    bit = self.render_node(node, context)
  File "D:\42_work\framework\venv\lib\site-packages\django\template\debug.py", line 79, in render_node
    return node.render(context)
  File "D:\42_work\framework\venv\lib\site-packages\django\template\loader_tags.py", line 113, in render
    compiled_parent = self.get_parent(context)
  File "D:\42_work\framework\venv\lib\site-packages\django\template\loader_tags.py", line 110, in get_parent
    return context.template.engine.get_template(parent)
  File "D:\42_work\framework\venv\lib\site-packages\django\template\engine.py", line 167, in get_template
    template, origin = self.find_template(template_name, dirs)
  File "D:\42_work\framework\venv\lib\site-packages\django\template\engine.py", line 141, in find_template
    source, display_name = loader(name, dirs)
  File "D:\42_work\framework\venv\lib\site-packages\django\template\loaders\base.py", line 13, in __call__
    return self.load_template(template_name, template_dirs)
  File "D:\42_work\framework\venv\lib\site-packages\django\template\loaders\base.py", line 23, in load_template
    template = Template(source, origin, template_name, self.engine)
  File "D:\42_work\framework\venv\lib\site-packages\django\template\base.py", line 190, in __init__
    self.nodelist = engine.compile_string(template_string, origin)
  File "D:\42_work\framework\venv\lib\site-packages\django\template\engine.py", line 261, in compile_string
    return parser.parse()
  File "D:\42_work\framework\venv\lib\site-packages\django\template\base.py", line 341, in parse
    compiled_result = compile_func(self, token)
  File "D:\42_work\framework\venv\lib\site-packages\django\template\defaulttags.py", line 1332, in spaceless
    nodelist = parser.parse(('endspaceless',))
  File "D:\42_work\framework\venv\lib\site-packages\django\template\base.py", line 341, in parse
    compiled_result = compile_func(self, token)
  File "D:\42_work\framework\venv\lib\site-packages\django\template\defaulttags.py", line 1014, in do_if
    nodelist = parser.parse(('elif', 'else', 'endif'))
  File "D:\42_work\framework\venv\lib\site-packages\django\template\base.py", line 341, in parse
    compiled_result = compile_func(self, token)
  File "D:\42_work\framework\venv\lib\site-packages\django\template\defaulttags.py", line 1013, in do_if
    condition = TemplateIfParser(parser, bits).parse()
  File "D:\42_work\framework\venv\lib\site-packages\django\template\defaulttags.py", line 945, in __init__
    super(TemplateIfParser, self).__init__(*args, **kwargs)
  File "D:\42_work\framework\venv\lib\site-packages\django\template\smartif.py", line 168, in __init__
    mapped_tokens.append(self.translate_token(token))
  File "D:\42_work\framework\venv\lib\site-packages\django\template\smartif.py", line 179, in translate_token
    return self.create_var(token)
  File "D:\42_work\framework\venv\lib\site-packages\django\template\defaulttags.py", line 948, in create_var
    return TemplateLiteral(self.template_parser.compile_filter(value), value)
  File "D:\42_work\framework\venv\lib\site-packages\django\template\base.py", line 423, in compile_filter
    return FilterExpression(token, self)
  File "D:\42_work\framework\venv\lib\site-packages\django\template\base.py", line 639, in __init__
    "from '%s'" % (token[upto:], token))
django.template.base.TemplateSyntaxError: Could not parse the remainder: '(url_forum' from '(url_forum'
[16/07/2015 02:49:07] :: [base:handle_uncaught_exception:django.request] [256] :: Internal Server Error: /
Traceback (most recent call last):
  File "D:\42_work\framework\venv\lib\site-packages\django\template\smartif.py", line 177, in translate_token
    op = OPERATORS[token]
KeyError: '(url_forum'

During handling of the above exception, another exception occurred:

Traceback (most recent call last):
  File "D:\42_work\framework\venv\lib\site-packages\django\core\handlers\base.py", line 132, in get_response
    response = wrapped_callback(request, *callback_args, **callback_kwargs)
  File "D:\42_work\framework\app\core\home.py", line 13, in index
    return render(request, 'core/home.html', {})
  File "D:\42_work\framework\venv\lib\site-packages\django\shortcuts.py", line 67, in render
    template_name, context, request=request, using=using)
  File "D:\42_work\framework\venv\lib\site-packages\django\template\loader.py", line 99, in render_to_string
    return template.render(context, request)
  File "D:\42_work\framework\venv\lib\site-packages\django\template\backends\django.py", line 74, in render
    return self.template.render(context)
  File "D:\42_work\framework\venv\lib\site-packages\django\template\base.py", line 209, in render
    return self._render(context)
  File "D:\42_work\framework\venv\lib\site-packages\django\template\base.py", line 201, in _render
    return self.nodelist.render(context)
  File "D:\42_work\framework\venv\lib\site-packages\django\template\base.py", line 903, in render
    bit = self.render_node(node, context)
  File "D:\42_work\framework\venv\lib\site-packages\django\template\debug.py", line 79, in render_node
    return node.render(context)
  File "D:\42_work\framework\venv\lib\site-packages\django\template\loader_tags.py", line 113, in render
    compiled_parent = self.get_parent(context)
  File "D:\42_work\framework\venv\lib\site-packages\django\template\loader_tags.py", line 110, in get_parent
    return context.template.engine.get_template(parent)
  File "D:\42_work\framework\venv\lib\site-packages\django\template\engine.py", line 167, in get_template
    template, origin = self.find_template(template_name, dirs)
  File "D:\42_work\framework\venv\lib\site-packages\django\template\engine.py", line 141, in find_template
    source, display_name = loader(name, dirs)
  File "D:\42_work\framework\venv\lib\site-packages\django\template\loaders\base.py", line 13, in __call__
    return self.load_template(template_name, template_dirs)
  File "D:\42_work\framework\venv\lib\site-packages\django\template\loaders\base.py", line 23, in load_template
    template = Template(source, origin, template_name, self.engine)
  File "D:\42_work\framework\venv\lib\site-packages\django\template\base.py", line 190, in __init__
    self.nodelist = engine.compile_string(template_string, origin)
  File "D:\42_work\framework\venv\lib\site-packages\django\template\engine.py", line 261, in compile_string
    return parser.parse()
  File "D:\42_work\framework\venv\lib\site-packages\django\template\base.py", line 341, in parse
    compiled_result = compile_func(self, token)
  File "D:\42_work\framework\venv\lib\site-packages\django\template\defaulttags.py", line 1332, in spaceless
    nodelist = parser.parse(('endspaceless',))
  File "D:\42_work\framework\venv\lib\site-packages\django\template\base.py", line 341, in parse
    compiled_result = compile_func(self, token)
  File "D:\42_work\framework\venv\lib\site-packages\django\template\defaulttags.py", line 1014, in do_if
    nodelist = parser.parse(('elif', 'else', 'endif'))
  File "D:\42_work\framework\venv\lib\site-packages\django\template\base.py", line 341, in parse
    compiled_result = compile_func(self, token)
  File "D:\42_work\framework\venv\lib\site-packages\django\template\defaulttags.py", line 1013, in do_if
    condition = TemplateIfParser(parser, bits).parse()
  File "D:\42_work\framework\venv\lib\site-packages\django\template\defaulttags.py", line 945, in __init__
    super(TemplateIfParser, self).__init__(*args, **kwargs)
  File "D:\42_work\framework\venv\lib\site-packages\django\template\smartif.py", line 168, in __init__
    mapped_tokens.append(self.translate_token(token))
  File "D:\42_work\framework\venv\lib\site-packages\django\template\smartif.py", line 179, in translate_token
    return self.create_var(token)
  File "D:\42_work\framework\venv\lib\site-packages\django\template\defaulttags.py", line 948, in create_var
    return TemplateLiteral(self.template_parser.compile_filter(value), value)
  File "D:\42_work\framework\venv\lib\site-packages\django\template\base.py", line 423, in compile_filter
    return FilterExpression(token, self)
  File "D:\42_work\framework\venv\lib\site-packages\django\template\base.py", line 639, in __init__
    "from '%s'" % (token[upto:], token))
django.template.base.TemplateSyntaxError: Could not parse the remainder: '(url_forum' from '(url_forum'
[16/07/2015 02:54:30] :: [base:get_response:django.request] [170] :: Not Found: /favicon.ico
[16/07/2015 02:12:58] :: [base:get_response:django.request] [170] :: Not Found: /favicon.ico
[16/07/2015 02:18:34] :: [base:handle_uncaught_exception:django.request] [256] :: Internal Server Error: /profil/ldap
Traceback (most recent call last):
  File "/home/chrysa/Bureau/42_work/framework/venv/lib/python3.4/site-packages/django/core/handlers/base.py", line 132, in get_response
    response = wrapped_callback(request, *callback_args, **callback_kwargs)
  File "/home/chrysa/Bureau/42_work/framework/app/ldap42/views.py", line 75, in login_ldap
    u[0].set_password(request.POST['password']).save()
AttributeError: 'NoneType' object has no attribute 'save'
[16/07/2015 02:21:29] :: [base:handle_uncaught_exception:django.request] [256] :: Internal Server Error: /profil/ldap
Traceback (most recent call last):
  File "/home/chrysa/Bureau/42_work/framework/venv/lib/python3.4/site-packages/django/core/handlers/base.py", line 132, in get_response
    response = wrapped_callback(request, *callback_args, **callback_kwargs)
  File "/home/chrysa/Bureau/42_work/framework/app/ldap42/views.py", line 76, in login_ldap
    u[0].set_password(request.POST['password']).save()
AttributeError: 'NoneType' object has no attribute 'save'
[16/07/2015 02:26:00] :: [base:handle_uncaught_exception:django.request] [256] :: Internal Server Error: /profil/ldap
Traceback (most recent call last):
  File "/home/chrysa/Bureau/42_work/framework/venv/lib/python3.4/site-packages/django/core/handlers/base.py", line 132, in get_response
    response = wrapped_callback(request, *callback_args, **callback_kwargs)
  File "/home/chrysa/Bureau/42_work/framework/app/ldap42/views.py", line 76, in login_ldap
    if not hashers.check_password(request.POST['password'], u[0]['password']):
TypeError: 'User' object is not subscriptable
