[05/08/2015 17:26:18] :: [base:handle_uncaught_exception:django.request] [256] :: Internal Server Error: /issue/reopen/test-issue/
Traceback (most recent call last):
  File "D:\42_work\framework\framework42_venv\lib\site-packages\django\core\handlers\base.py", line 132, in get_response
    response = wrapped_callback(request, *callback_args, **callback_kwargs)
  File "D:\42_work\framework\framework42_venv\lib\site-packages\django\contrib\auth\decorators.py", line 22, in _wrapped_view
    return view_func(request, *args, **kwargs)
  File "D:\42_work\framework\framework42\issues\views.py", line 132, in reopen_issue
    if issue.Status == 'close':
AttributeError: 'QuerySet' object has no attribute 'Status'
[05/08/2015 17:28:14] :: [base:handle_uncaught_exception:django.request] [256] :: Internal Server Error: /issue/reopen/test-issue/
Traceback (most recent call last):
  File "D:\42_work\framework\framework42_venv\lib\site-packages\django\core\handlers\base.py", line 132, in get_response
    response = wrapped_callback(request, *callback_args, **callback_kwargs)
  File "D:\42_work\framework\framework42_venv\lib\site-packages\django\contrib\auth\decorators.py", line 22, in _wrapped_view
    return view_func(request, *args, **kwargs)
  File "D:\42_work\framework\framework42\issues\views.py", line 132, in reopen_issue
    if issue.Status == 'close':
AttributeError: 'QuerySet' object has no attribute 'Status'
[05/08/2015 17:28:33] :: [base:handle_uncaught_exception:django.request] [256] :: Internal Server Error: /issue/reopen/test-issue/
Traceback (most recent call last):
  File "D:\42_work\framework\framework42_venv\lib\site-packages\django\core\handlers\base.py", line 132, in get_response
    response = wrapped_callback(request, *callback_args, **callback_kwargs)
  File "D:\42_work\framework\framework42_venv\lib\site-packages\django\contrib\auth\decorators.py", line 22, in _wrapped_view
    return view_func(request, *args, **kwargs)
  File "D:\42_work\framework\framework42\issues\views.py", line 132, in reopen_issue
    if issue.Status == 'close':
AttributeError: 'QuerySet' object has no attribute 'Status'
[05/08/2015 17:29:01] :: [base:handle_uncaught_exception:django.request] [256] :: Internal Server Error: /issue/reopen/test-issue/
Traceback (most recent call last):
  File "D:\42_work\framework\framework42_venv\lib\site-packages\django\core\handlers\base.py", line 132, in get_response
    response = wrapped_callback(request, *callback_args, **callback_kwargs)
  File "D:\42_work\framework\framework42_venv\lib\site-packages\django\contrib\auth\decorators.py", line 22, in _wrapped_view
    return view_func(request, *args, **kwargs)
  File "D:\42_work\framework\framework42\issues\views.py", line 132, in reopen_issue
    if issue.Status == 'close':
AttributeError: 'QuerySet' object has no attribute 'Status'
[05/08/2015 17:44:04] :: [base:handle_uncaught_exception:django.request] [256] :: Internal Server Error: /issue/respond/test-issue/
Traceback (most recent call last):
  File "D:\42_work\framework\framework42_venv\lib\site-packages\django\core\handlers\base.py", line 132, in get_response
    response = wrapped_callback(request, *callback_args, **callback_kwargs)
  File "D:\42_work\framework\framework42_venv\lib\site-packages\django\contrib\auth\decorators.py", line 22, in _wrapped_view
    return view_func(request, *args, **kwargs)
  File "D:\42_work\framework\framework42\issues\views.py", line 89, in respond_issue
    if (request.user.is_staff or request.user.is_supersuer) is not True:
  File "D:\42_work\framework\framework42_venv\lib\site-packages\django\utils\functional.py", line 227, in inner
    return func(self._wrapped, *args)
AttributeError: 'User' object has no attribute 'is_supersuer'
[05/08/2015 18:07:18] :: [base:handle_uncaught_exception:django.request] [256] :: Internal Server Error: /issue/respond/test-issue/
Traceback (most recent call last):
  File "D:\42_work\framework\framework42_venv\lib\site-packages\django\core\handlers\base.py", line 132, in get_response
    response = wrapped_callback(request, *callback_args, **callback_kwargs)
  File "D:\42_work\framework\framework42_venv\lib\site-packages\django\contrib\auth\decorators.py", line 22, in _wrapped_view
    return view_func(request, *args, **kwargs)
  File "D:\42_work\framework\framework42\issues\views.py", line 122, in respond_issue
    reverse('view_issue', kwargs={'issue': self.issue.slug}),
NameError: name 'self' is not defined
[05/08/2015 20:14:44] :: [base:handle_uncaught_exception:django.request] [256] :: Internal Server Error: /issue/reopen/test-issue/
Traceback (most recent call last):
  File "D:\42_work\framework\framework42_venv\lib\site-packages\django\core\handlers\base.py", line 132, in get_response
    response = wrapped_callback(request, *callback_args, **callback_kwargs)
  File "D:\42_work\framework\framework42_venv\lib\site-packages\django\contrib\auth\decorators.py", line 22, in _wrapped_view
    return view_func(request, *args, **kwargs)
  File "D:\42_work\framework\framework42\issues\views.py", line 149, in reopen_issue
    if request.user == issue.Autor or (request.user.is_staff or request.user.is_superuser) is True:
AttributeError: 'QuerySet' object has no attribute 'Autor'
[05/08/2015 20:14:44] :: [base:handle_uncaught_exception:django.request] [256] :: Internal Server Error: /issue/view/test-issue/
Traceback (most recent call last):
  File "D:\42_work\framework\framework42_venv\lib\site-packages\django\core\handlers\base.py", line 132, in get_response
    response = wrapped_callback(request, *callback_args, **callback_kwargs)
  File "D:\42_work\framework\framework42_venv\lib\site-packages\django\contrib\auth\decorators.py", line 22, in _wrapped_view
    return view_func(request, *args, **kwargs)
  File "D:\42_work\framework\framework42\issues\views.py", line 132, in view_issue
    issue = Issue.objects.get(slug=issue)[0]
TypeError: 'Issue' object does not support indexing
[05/08/2015 20:18:08] :: [base:handle_uncaught_exception:django.request] [256] :: Internal Server Error: /issue/reopen/test-issue/
Traceback (most recent call last):
  File "D:\42_work\framework\framework42_venv\lib\site-packages\django\core\handlers\base.py", line 132, in get_response
    response = wrapped_callback(request, *callback_args, **callback_kwargs)
  File "D:\42_work\framework\framework42_venv\lib\site-packages\django\contrib\auth\decorators.py", line 22, in _wrapped_view
    return view_func(request, *args, **kwargs)
  File "D:\42_work\framework\framework42\issues\views.py", line 149, in reopen_issue
    if request.user == issue.Autor or (request.user.is_staff or request.user.is_superuser) is True:
AttributeError: 'QuerySet' object has no attribute 'Autor'
[05/08/2015 20:18:09] :: [base:handle_uncaught_exception:django.request] [256] :: Internal Server Error: /issue/view/test-issue/
Traceback (most recent call last):
  File "D:\42_work\framework\framework42_venv\lib\site-packages\django\core\handlers\base.py", line 132, in get_response
    response = wrapped_callback(request, *callback_args, **callback_kwargs)
  File "D:\42_work\framework\framework42_venv\lib\site-packages\django\contrib\auth\decorators.py", line 22, in _wrapped_view
    return view_func(request, *args, **kwargs)
  File "D:\42_work\framework\framework42\issues\views.py", line 132, in view_issue
    issue = Issue.objects.get(slug=issue)[0]
TypeError: 'Issue' object does not support indexing
[05/08/2015 20:19:09] :: [base:handle_uncaught_exception:django.request] [256] :: Internal Server Error: /issue/reopen/test-issue/
Traceback (most recent call last):
  File "D:\42_work\framework\framework42_venv\lib\site-packages\django\core\handlers\base.py", line 132, in get_response
    response = wrapped_callback(request, *callback_args, **callback_kwargs)
  File "D:\42_work\framework\framework42_venv\lib\site-packages\django\contrib\auth\decorators.py", line 22, in _wrapped_view
    return view_func(request, *args, **kwargs)
  File "D:\42_work\framework\framework42\issues\views.py", line 149, in reopen_issue
    if request.user == issue.Autor or (request.user.is_staff or request.user.is_superuser) is True:
AttributeError: 'QuerySet' object has no attribute 'Autor'
[05/08/2015 20:19:09] :: [base:handle_uncaught_exception:django.request] [256] :: Internal Server Error: /issue/view/test-issue/
Traceback (most recent call last):
  File "D:\42_work\framework\framework42_venv\lib\site-packages\django\core\handlers\base.py", line 132, in get_response
    response = wrapped_callback(request, *callback_args, **callback_kwargs)
  File "D:\42_work\framework\framework42_venv\lib\site-packages\django\contrib\auth\decorators.py", line 22, in _wrapped_view
    return view_func(request, *args, **kwargs)
  File "D:\42_work\framework\framework42\issues\views.py", line 132, in view_issue
    issue = Issue.objects.get(slug=issue)[0]
TypeError: 'Issue' object does not support indexing
[05/08/2015 20:19:20] :: [base:handle_uncaught_exception:django.request] [256] :: Internal Server Error: /issue/reopen/test-issue/
Traceback (most recent call last):
  File "D:\42_work\framework\framework42_venv\lib\site-packages\django\core\handlers\base.py", line 132, in get_response
    response = wrapped_callback(request, *callback_args, **callback_kwargs)
  File "D:\42_work\framework\framework42_venv\lib\site-packages\django\contrib\auth\decorators.py", line 22, in _wrapped_view
    return view_func(request, *args, **kwargs)
  File "D:\42_work\framework\framework42\issues\views.py", line 149, in reopen_issue
    if request.user == issue.Autor or (request.user.is_staff or request.user.is_superuser) is True:
AttributeError: 'QuerySet' object has no attribute 'Autor'
[05/08/2015 20:19:21] :: [base:handle_uncaught_exception:django.request] [256] :: Internal Server Error: /issue/view/test-issue/
Traceback (most recent call last):
  File "D:\42_work\framework\framework42_venv\lib\site-packages\django\core\handlers\base.py", line 132, in get_response
    response = wrapped_callback(request, *callback_args, **callback_kwargs)
  File "D:\42_work\framework\framework42_venv\lib\site-packages\django\contrib\auth\decorators.py", line 22, in _wrapped_view
    return view_func(request, *args, **kwargs)
  File "D:\42_work\framework\framework42\issues\views.py", line 132, in view_issue
    issue = Issue.objects.get(slug=issue)[0]
TypeError: 'Issue' object does not support indexing
[05/08/2015 20:19:46] :: [base:handle_uncaught_exception:django.request] [256] :: Internal Server Error: /issue/reopen/test-issue/
Traceback (most recent call last):
  File "D:\42_work\framework\framework42_venv\lib\site-packages\django\core\handlers\base.py", line 132, in get_response
    response = wrapped_callback(request, *callback_args, **callback_kwargs)
  File "D:\42_work\framework\framework42_venv\lib\site-packages\django\contrib\auth\decorators.py", line 22, in _wrapped_view
    return view_func(request, *args, **kwargs)
  File "D:\42_work\framework\framework42\issues\views.py", line 150, in reopen_issue
    if request.user == issue.Autor or (request.user.is_staff or request.user.is_superuser) is True:
AttributeError: 'QuerySet' object has no attribute 'Autor'
[05/08/2015 20:19:46] :: [base:handle_uncaught_exception:django.request] [256] :: Internal Server Error: /issue/view/test-issue/
Traceback (most recent call last):
  File "D:\42_work\framework\framework42_venv\lib\site-packages\django\core\handlers\base.py", line 132, in get_response
    response = wrapped_callback(request, *callback_args, **callback_kwargs)
  File "D:\42_work\framework\framework42_venv\lib\site-packages\django\contrib\auth\decorators.py", line 22, in _wrapped_view
    return view_func(request, *args, **kwargs)
  File "D:\42_work\framework\framework42\issues\views.py", line 132, in view_issue
    issue = Issue.objects.get(slug=issue)[0]
TypeError: 'Issue' object does not support indexing
[05/08/2015 20:20:08] :: [base:handle_uncaught_exception:django.request] [256] :: Internal Server Error: /issue/reopen/test-issue/
Traceback (most recent call last):
  File "D:\42_work\framework\framework42_venv\lib\site-packages\django\core\handlers\base.py", line 132, in get_response
    response = wrapped_callback(request, *callback_args, **callback_kwargs)
  File "D:\42_work\framework\framework42_venv\lib\site-packages\django\contrib\auth\decorators.py", line 22, in _wrapped_view
    return view_func(request, *args, **kwargs)
  File "D:\42_work\framework\framework42\issues\views.py", line 150, in reopen_issue
    if request.user == issue.Autor or (request.user.is_staff or request.user.is_superuser) is True:
AttributeError: 'QuerySet' object has no attribute 'Autor'
[05/08/2015 20:20:37] :: [base:handle_uncaught_exception:django.request] [256] :: Internal Server Error: /issue/reopen/test-issue/
Traceback (most recent call last):
  File "D:\42_work\framework\framework42_venv\lib\site-packages\django\core\handlers\base.py", line 132, in get_response
    response = wrapped_callback(request, *callback_args, **callback_kwargs)
  File "D:\42_work\framework\framework42_venv\lib\site-packages\django\contrib\auth\decorators.py", line 22, in _wrapped_view
    return view_func(request, *args, **kwargs)
  File "D:\42_work\framework\framework42\issues\views.py", line 150, in reopen_issue
    if request.user == issue.Autor or (request.user.is_staff or request.user.is_superuser) is True:
AttributeError: 'QuerySet' object has no attribute 'Autor'
[05/08/2015 20:20:57] :: [base:handle_uncaught_exception:django.request] [256] :: Internal Server Error: /issue/reopen/test-issue/
Traceback (most recent call last):
  File "D:\42_work\framework\framework42_venv\lib\site-packages\django\core\handlers\base.py", line 132, in get_response
    response = wrapped_callback(request, *callback_args, **callback_kwargs)
  File "D:\42_work\framework\framework42_venv\lib\site-packages\django\contrib\auth\decorators.py", line 22, in _wrapped_view
    return view_func(request, *args, **kwargs)
  File "D:\42_work\framework\framework42\issues\views.py", line 151, in reopen_issue
    if request.user == issue.Autor or (request.user.is_staff or request.user.is_superuser) is True:
AttributeError: 'QuerySet' object has no attribute 'Autor'
[05/08/2015 20:23:52] :: [base:handle_uncaught_exception:django.request] [256] :: Internal Server Error: /issue/reopen/test-issue/
Traceback (most recent call last):
  File "D:\42_work\framework\framework42_venv\lib\site-packages\django\core\handlers\base.py", line 132, in get_response
    response = wrapped_callback(request, *callback_args, **callback_kwargs)
  File "D:\42_work\framework\framework42_venv\lib\site-packages\django\contrib\auth\decorators.py", line 22, in _wrapped_view
    return view_func(request, *args, **kwargs)
  File "D:\42_work\framework\framework42\issues\views.py", line 152, in reopen_issue
    if request.user == issue.Autor or request.user.is_staff or request.user.is_superuser:
AttributeError: 'QuerySet' object has no attribute 'Autor'
[05/08/2015 22:41:05] :: [base:handle_uncaught_exception:django.request] [256] :: Internal Server Error: /issue/view/invalid-issue/
Traceback (most recent call last):
  File "D:\42_work\framework\framework42_venv\lib\site-packages\django\core\handlers\base.py", line 132, in get_response
    response = wrapped_callback(request, *callback_args, **callback_kwargs)
  File "D:\42_work\framework\framework42_venv\lib\site-packages\django\contrib\auth\decorators.py", line 22, in _wrapped_view
    return view_func(request, *args, **kwargs)
  File "D:\42_work\framework\framework42\issues\views.py", line 132, in view_issue
    issue = Issue.objects.get(slug=issue)
  File "D:\42_work\framework\framework42_venv\lib\site-packages\django\db\models\manager.py", line 127, in manager_method
    return getattr(self.get_queryset(), name)(*args, **kwargs)
  File "D:\42_work\framework\framework42_venv\lib\site-packages\django\db\models\query.py", line 334, in get
    self.model._meta.object_name
issues.models.DoesNotExist: Issue matching query does not exist.
[05/08/2015 22:41:05] :: [base:handle_uncaught_exception:django.request] [256] :: Internal Server Error: /issue/view/invalid-issue/
Traceback (most recent call last):
  File "D:\42_work\framework\framework42_venv\lib\site-packages\django\core\handlers\base.py", line 132, in get_response
    response = wrapped_callback(request, *callback_args, **callback_kwargs)
  File "D:\42_work\framework\framework42_venv\lib\site-packages\django\contrib\auth\decorators.py", line 22, in _wrapped_view
    return view_func(request, *args, **kwargs)
  File "D:\42_work\framework\framework42\issues\views.py", line 132, in view_issue
    issue = Issue.objects.get(slug=issue)
  File "D:\42_work\framework\framework42_venv\lib\site-packages\django\db\models\manager.py", line 127, in manager_method
    return getattr(self.get_queryset(), name)(*args, **kwargs)
  File "D:\42_work\framework\framework42_venv\lib\site-packages\django\db\models\query.py", line 334, in get
    self.model._meta.object_name
issues.models.DoesNotExist: Issue matching query does not exist.
[05/08/2015 22:41:05] :: [base:handle_uncaught_exception:django.request] [256] :: Internal Server Error: /issue/view/invalid-issue/
Traceback (most recent call last):
  File "D:\42_work\framework\framework42_venv\lib\site-packages\django\core\handlers\base.py", line 132, in get_response
    response = wrapped_callback(request, *callback_args, **callback_kwargs)
  File "D:\42_work\framework\framework42_venv\lib\site-packages\django\contrib\auth\decorators.py", line 22, in _wrapped_view
    return view_func(request, *args, **kwargs)
  File "D:\42_work\framework\framework42\issues\views.py", line 132, in view_issue
    issue = Issue.objects.get(slug=issue)
  File "D:\42_work\framework\framework42_venv\lib\site-packages\django\db\models\manager.py", line 127, in manager_method
    return getattr(self.get_queryset(), name)(*args, **kwargs)
  File "D:\42_work\framework\framework42_venv\lib\site-packages\django\db\models\query.py", line 334, in get
    self.model._meta.object_name
issues.models.DoesNotExist: Issue matching query does not exist.
[05/08/2015 22:45:01] :: [base:handle_uncaught_exception:django.request] [256] :: Internal Server Error: /issue/view/invalid-issue/
Traceback (most recent call last):
  File "D:\42_work\framework\framework42_venv\lib\site-packages\django\core\handlers\base.py", line 132, in get_response
    response = wrapped_callback(request, *callback_args, **callback_kwargs)
  File "D:\42_work\framework\framework42_venv\lib\site-packages\django\contrib\auth\decorators.py", line 22, in _wrapped_view
    return view_func(request, *args, **kwargs)
  File "D:\42_work\framework\framework42\issues\views.py", line 132, in view_issue
    issue = Issue.objects.get_or_404(slug=issue)
AttributeError: 'Manager' object has no attribute 'get_or_404'
[05/08/2015 22:45:01] :: [base:handle_uncaught_exception:django.request] [256] :: Internal Server Error: /issue/view/invalid-issue/
Traceback (most recent call last):
  File "D:\42_work\framework\framework42_venv\lib\site-packages\django\core\handlers\base.py", line 132, in get_response
    response = wrapped_callback(request, *callback_args, **callback_kwargs)
  File "D:\42_work\framework\framework42_venv\lib\site-packages\django\contrib\auth\decorators.py", line 22, in _wrapped_view
    return view_func(request, *args, **kwargs)
  File "D:\42_work\framework\framework42\issues\views.py", line 132, in view_issue
    issue = Issue.objects.get_or_404(slug=issue)
AttributeError: 'Manager' object has no attribute 'get_or_404'
[05/08/2015 22:45:01] :: [base:handle_uncaught_exception:django.request] [256] :: Internal Server Error: /issue/view/invalid-issue/
Traceback (most recent call last):
  File "D:\42_work\framework\framework42_venv\lib\site-packages\django\core\handlers\base.py", line 132, in get_response
    response = wrapped_callback(request, *callback_args, **callback_kwargs)
  File "D:\42_work\framework\framework42_venv\lib\site-packages\django\contrib\auth\decorators.py", line 22, in _wrapped_view
    return view_func(request, *args, **kwargs)
  File "D:\42_work\framework\framework42\issues\views.py", line 132, in view_issue
    issue = Issue.objects.get_or_404(slug=issue)
AttributeError: 'Manager' object has no attribute 'get_or_404'
[05/08/2015 22:45:01] :: [base:handle_uncaught_exception:django.request] [256] :: Internal Server Error: /issue/view/test-issue/
Traceback (most recent call last):
  File "D:\42_work\framework\framework42_venv\lib\site-packages\django\core\handlers\base.py", line 132, in get_response
    response = wrapped_callback(request, *callback_args, **callback_kwargs)
  File "D:\42_work\framework\framework42_venv\lib\site-packages\django\contrib\auth\decorators.py", line 22, in _wrapped_view
    return view_func(request, *args, **kwargs)
  File "D:\42_work\framework\framework42\issues\views.py", line 132, in view_issue
    issue = Issue.objects.get_or_404(slug=issue)
AttributeError: 'Manager' object has no attribute 'get_or_404'
[05/08/2015 22:45:01] :: [base:handle_uncaught_exception:django.request] [256] :: Internal Server Error: /issue/view/test-issue/
Traceback (most recent call last):
  File "D:\42_work\framework\framework42_venv\lib\site-packages\django\core\handlers\base.py", line 132, in get_response
    response = wrapped_callback(request, *callback_args, **callback_kwargs)
  File "D:\42_work\framework\framework42_venv\lib\site-packages\django\contrib\auth\decorators.py", line 22, in _wrapped_view
    return view_func(request, *args, **kwargs)
  File "D:\42_work\framework\framework42\issues\views.py", line 132, in view_issue
    issue = Issue.objects.get_or_404(slug=issue)
AttributeError: 'Manager' object has no attribute 'get_or_404'
[05/08/2015 22:45:19] :: [base:handle_uncaught_exception:django.request] [256] :: Internal Server Error: /issue/view/invalid-issue/
Traceback (most recent call last):
  File "D:\42_work\framework\framework42_venv\lib\site-packages\django\core\handlers\base.py", line 132, in get_response
    response = wrapped_callback(request, *callback_args, **callback_kwargs)
  File "D:\42_work\framework\framework42_venv\lib\site-packages\django\contrib\auth\decorators.py", line 22, in _wrapped_view
    return view_func(request, *args, **kwargs)
  File "D:\42_work\framework\framework42\issues\views.py", line 132, in view_issue
    issue = Issue.objects.get_or_404(slug=issue)
AttributeError: 'Manager' object has no attribute 'get_or_404'
[05/08/2015 22:45:19] :: [base:handle_uncaught_exception:django.request] [256] :: Internal Server Error: /issue/view/invalid-issue/
Traceback (most recent call last):
  File "D:\42_work\framework\framework42_venv\lib\site-packages\django\core\handlers\base.py", line 132, in get_response
    response = wrapped_callback(request, *callback_args, **callback_kwargs)
  File "D:\42_work\framework\framework42_venv\lib\site-packages\django\contrib\auth\decorators.py", line 22, in _wrapped_view
    return view_func(request, *args, **kwargs)
  File "D:\42_work\framework\framework42\issues\views.py", line 132, in view_issue
    issue = Issue.objects.get_or_404(slug=issue)
AttributeError: 'Manager' object has no attribute 'get_or_404'
[05/08/2015 22:45:20] :: [base:handle_uncaught_exception:django.request] [256] :: Internal Server Error: /issue/view/invalid-issue/
Traceback (most recent call last):
  File "D:\42_work\framework\framework42_venv\lib\site-packages\django\core\handlers\base.py", line 132, in get_response
    response = wrapped_callback(request, *callback_args, **callback_kwargs)
  File "D:\42_work\framework\framework42_venv\lib\site-packages\django\contrib\auth\decorators.py", line 22, in _wrapped_view
    return view_func(request, *args, **kwargs)
  File "D:\42_work\framework\framework42\issues\views.py", line 132, in view_issue
    issue = Issue.objects.get_or_404(slug=issue)
AttributeError: 'Manager' object has no attribute 'get_or_404'
[05/08/2015 22:45:20] :: [base:handle_uncaught_exception:django.request] [256] :: Internal Server Error: /issue/view/test-issue/
Traceback (most recent call last):
  File "D:\42_work\framework\framework42_venv\lib\site-packages\django\core\handlers\base.py", line 132, in get_response
    response = wrapped_callback(request, *callback_args, **callback_kwargs)
  File "D:\42_work\framework\framework42_venv\lib\site-packages\django\contrib\auth\decorators.py", line 22, in _wrapped_view
    return view_func(request, *args, **kwargs)
  File "D:\42_work\framework\framework42\issues\views.py", line 132, in view_issue
    issue = Issue.objects.get_or_404(slug=issue)
AttributeError: 'Manager' object has no attribute 'get_or_404'
[05/08/2015 22:45:20] :: [base:handle_uncaught_exception:django.request] [256] :: Internal Server Error: /issue/view/test-issue/
Traceback (most recent call last):
  File "D:\42_work\framework\framework42_venv\lib\site-packages\django\core\handlers\base.py", line 132, in get_response
    response = wrapped_callback(request, *callback_args, **callback_kwargs)
  File "D:\42_work\framework\framework42_venv\lib\site-packages\django\contrib\auth\decorators.py", line 22, in _wrapped_view
    return view_func(request, *args, **kwargs)
  File "D:\42_work\framework\framework42\issues\views.py", line 132, in view_issue
    issue = Issue.objects.get_or_404(slug=issue)
AttributeError: 'Manager' object has no attribute 'get_or_404'
[05/08/2015 23:47:13] :: [base:handle_uncaught_exception:django.request] [256] :: Internal Server Error: /issue/reopen/invalid-issue/
Traceback (most recent call last):
  File "D:\42_work\framework\framework42_venv\lib\site-packages\django\core\handlers\base.py", line 132, in get_response
    response = wrapped_callback(request, *callback_args, **callback_kwargs)
  File "D:\42_work\framework\framework42_venv\lib\site-packages\django\contrib\auth\decorators.py", line 22, in _wrapped_view
    return view_func(request, *args, **kwargs)
  File "D:\42_work\framework\framework42\issues\views.py", line 154, in reopen_issue
    issue = Issue.objects.filter(slug=issue)[0]
  File "D:\42_work\framework\framework42_venv\lib\site-packages\django\db\models\query.py", line 201, in __getitem__
    return list(qs)[0]
IndexError: list index out of range
[05/08/2015 23:47:13] :: [base:handle_uncaught_exception:django.request] [256] :: Internal Server Error: /issue/reopen/invalid-issue/
Traceback (most recent call last):
  File "D:\42_work\framework\framework42_venv\lib\site-packages\django\core\handlers\base.py", line 132, in get_response
    response = wrapped_callback(request, *callback_args, **callback_kwargs)
  File "D:\42_work\framework\framework42_venv\lib\site-packages\django\contrib\auth\decorators.py", line 22, in _wrapped_view
    return view_func(request, *args, **kwargs)
  File "D:\42_work\framework\framework42\issues\views.py", line 154, in reopen_issue
    issue = Issue.objects.filter(slug=issue)[0]
  File "D:\42_work\framework\framework42_venv\lib\site-packages\django\db\models\query.py", line 201, in __getitem__
    return list(qs)[0]
IndexError: list index out of range
[05/08/2015 23:47:13] :: [base:handle_uncaught_exception:django.request] [256] :: Internal Server Error: /issue/reopen/invalid-issue/
Traceback (most recent call last):
  File "D:\42_work\framework\framework42_venv\lib\site-packages\django\core\handlers\base.py", line 132, in get_response
    response = wrapped_callback(request, *callback_args, **callback_kwargs)
  File "D:\42_work\framework\framework42_venv\lib\site-packages\django\contrib\auth\decorators.py", line 22, in _wrapped_view
    return view_func(request, *args, **kwargs)
  File "D:\42_work\framework\framework42\issues\views.py", line 154, in reopen_issue
    issue = Issue.objects.filter(slug=issue)[0]
  File "D:\42_work\framework\framework42_venv\lib\site-packages\django\db\models\query.py", line 201, in __getitem__
    return list(qs)[0]
IndexError: list index out of range
